Workbook

Sheet SQL
A1: select cr.includename, cr.isinactive, cr.name, LOWER(cr.scriptid) as record_id, cf.fieldtype, cf.fieldvaluetype, cf.fieldvaluetyperecord, cf.name, LOWER(cf.scriptid) as field_id from customrecordtype cr join customfield cf on cf.recordtype = cr.internalid where cr.scriptid like '%TWC%' order by cr.scriptid, cf.scriptid

Sheet LIVE
A1: includename | B1: isinactive | C1: name | D1: record_id | E1: TABLE IN SB | F1: fieldtype | G1: fieldvaluetype | H1: fieldvaluetyperecord | I1: name_0 | J1: field_id | K1: IN SB
A2: T | B2: F | C2: OSSMTWC - AWL Type | D2: customrecord_ossm_twc_awl_type | E2: =VLOOKUP(D2,'TABLES SB'!D:D,1,FALSE) -> customrecord_ossm_twc_awl_type | K2: =IF(J2="","",VLOOKUP(J2,SB!I:I,1,FALSE))
A3: T | B3: F | C3: OSSMTWC - FE Last Test Result | D3: customrecord_ossm_twc_fe_last_test_res | E3: =VLOOKUP(D3,'TABLES SB'!D:D,1,FALSE) -> customrecord_ossm_twc_fe_last_test_res | K3: =IF(J3="","",VLOOKUP(J3,SB!I:I,1,FALSE))
A4: T | B4: F | C4: OSSMTWC - FE Type | D4: customrecord_ossm_twc_fe_type | E4: =VLOOKUP(D4,'TABLES SB'!D:D,1,FALSE) -> customrecord_ossm_twc_fe_type | K4: =IF(J4="","",VLOOKUP(J4,SB!I:I,1,FALSE))
A5: T | B5: F | C5: OSSMTWC - FIRE EXTINGUISHER | D5: customrecord_ossm_twc_fire_extinguisher | E5: =VLOOKUP(D5,'TABLES SB'!D:D,1,FALSE) -> customrecord_ossm_twc_fire_extinguisher | F5: RECORD | G5: List/Record | H5: 1071 | I5: Accommodation | J5: custrecord_twc_fe_acc | K5: =IF(J5="","",VLOOKUP(J5,SB!I:I,1,FALSE)) -> custrecord_twc_fe_acc
A6: T | B6: F | C6: OSSMTWC - FIRE EXTINGUISHER | D6: customrecord_ossm_twc_fire_extinguisher | E6: =VLOOKUP(D6,'TABLES SB'!D:D,1,FALSE) -> customrecord_ossm_twc_fire_extinguisher | F6: RECORD | G6: Text Area | I6: Comments | J6: custrecord_twc_fe_comments | K6: =IF(J6="","",VLOOKUP(J6,SB!I:I,1,FALSE)) -> custrecord_twc_fe_comments
A7: T | B7: F | C7: OSSMTWC - FIRE EXTINGUISHER | D7: customrecord_ossm_twc_fire_extinguisher | E7: =VLOOKUP(D7,'TABLES SB'!D:D,1,FALSE) -> customrecord_ossm_twc_fire_extinguisher | F7: RECORD | G7: Free-Form Text | I7: Fire Extinguisher ID | J7: custrecord_twc_fe_id | K7: =IF(J7="","",VLOOKUP(J7,SB!I:I,1,FALSE)) -> custrecord_twc_fe_id
A8: T | B8: F | C8: OSSMTWC - FIRE EXTINGUISHER | D8: customrecord_ossm_twc_fire_extinguisher | E8: =VLOOKUP(D8,'TABLES SB'!D:D,1,FALSE) -> customrecord_ossm_twc_fire_extinguisher | F8: RECORD | G8: Date | I8: Installed Date | J8: custrecord_twc_fe_inst_date | K8: =IF(J8="","",VLOOKUP(J8,SB!I:I,1,FALSE)) -> custrecord_twc_fe_inst_date
A9: T | B9: F | C9: OSSMTWC - FIRE EXTINGUISHER | D9: customrecord_ossm_twc_fire_extinguisher | E9: =VLOOKUP(D9,'TABLES SB'!D:D,1,FALSE) -> customrecord_ossm_twc_fire_extinguisher | F9: RECORD | G9: Date | I9: Refill Date | J9: custrecord_twc_fe_refill_date | K9: =IF(J9="","",VLOOKUP(J9,SB!I:I,1,FALSE)) -> custrecord_twc_fe_refill_date
A10: T | B10: F | C10: OSSMTWC - FIRE EXTINGUISHER | D10: customrecord_ossm_twc_fire_extinguisher | E10: =VLOOKUP(D10,'TABLES SB'!D:D,1,FALSE) -> customrecord_ossm_twc_fire_extinguisher | F10: RECORD | G10: List/Record | H10: 1148 | I10: Site | J10: custrecord_twc_fe_site | K10: =IF(J10="","",VLOOKUP(J10,SB!I:I,1,FALSE)) -> custrecord_twc_fe_site
A11: T | B11: F | C11: OSSMTWC - FIRE EXTINGUISHER | D11: customrecord_ossm_twc_fire_extinguisher | E11: =VLOOKUP(D11,'TABLES SB'!D:D,1,FALSE) -> customrecord_ossm_twc_fire_extinguisher | F11: RECORD | G11: List/Record | H11: 1803 | I11: FE Status | J11: custrecord_twc_fe_status | K11: =IF(J11="","",VLOOKUP(J11,SB!I:I,1,FALSE)) -> custrecord_twc_fe_status
A12: T | B12: F | C12: OSSMTWC - FIRE EXTINGUISHER | D12: customrecord_ossm_twc_fire_extinguisher | E12: =VLOOKUP(D12,'TABLES SB'!D:D,1,FALSE) -> customrecord_ossm_twc_fire_extinguisher | F12: RECORD | G12: List/Record | H12: 1801 | I12: FE Type | J12: custrecord_twc_fe_ty | K12: =IF(J12="","",VLOOKUP(J12,SB!I:I,1,FALSE)) -> custrecord_twc_fe_ty
A13: T | B13: F | C13: OSSMTWC - FIRE EXTINGUISHER | D13: customrecord_ossm_twc_fire_extinguisher | E13: =VLOOKUP(D13,'TABLES SB'!D:D,1,FALSE) -> customrecord_ossm_twc_fire_extinguisher | F13: RECORD | G13: Integer Number | I13: Year of Manufacture | J13: custrecord_twc_fe_yom | K13: =IF(J13="","",VLOOKUP(J13,SB!I:I,1,FALSE)) -> custrecord_twc_fe_yom
A14: T | B14: F | C14: OSSMTWC - FIRE EXTINGUISHER | D14: customrecord_ossm_twc_fire_extinguisher | E14: =VLOOKUP(D14,'TABLES SB'!D:D,1,FALSE) -> customrecord_ossm_twc_fire_extinguisher | F14: RECORD | G14: List/Record | H14: 1800 | I14: Last Test Result | J14: custrecord_twc_last_test_res | K14: =IF(J14="","",VLOOKUP(J14,SB!I:I,1,FALSE)) -> custrecord_twc_last_test_res
A15: T | B15: F | C15: OSSMTWC - FIRE EXTINGUISHER | D15: customrecord_ossm_twc_fire_extinguisher | E15: =VLOOKUP(D15,'TABLES SB'!D:D,1,FALSE) -> customrecord_ossm_twc_fire_extinguisher | F15: RECORD | G15: Free-Form Text | I15: Location | J15: custrecord_twc_location | K15: =IF(J15="","",VLOOKUP(J15,SB!I:I,1,FALSE)) -> custrecord_twc_location
A16: F | B16: T | C16: OSSMTWC - Accommodation | D16: customrecord_twc_ac | E16: =VLOOKUP(D16,'TABLES SB'!D:D,1,FALSE) -> customrecord_twc_ac | F16: RECORD | G16: List/Record | H16: 1024 | I16: AC Feed Phase | J16: custrecord_twc_ac_ac_feed_phase | K16: =IF(J16="","",VLOOKUP(J16,SB!I:I,1,FALSE)) -> custrecord_twc_ac_ac_feed_phase
A17: F | B17: T | C17: OSSMTWC - Accommodation | D17: customrecord_twc_ac | E17: =VLOOKUP(D17,'TABLES SB'!D:D,1,FALSE) -> customrecord_twc_ac | F17: RECORD | G17: Free-Form Text | I17: Comments | J17: custrecord_twc_ac_comments | K17: =IF(J17="","",VLOOKUP(J17,SB!I:I,1,FALSE)) -> custrecord_twc_ac_comments
A18: F | B18: T | C18: OSSMTWC - Accommodation | D18: customrecord_twc_ac | E18: =VLOOKUP(D18,'TABLES SB'!D:D,1,FALSE) -> customrecord_twc_ac | F18: RECORD | G18: List/Record | H18: 1060 | I18: Facilities Services | J18: custrecord_twc_ac_fac_svc | K18: =IF(J18="","",VLOOKUP(J18,SB!I:I,1,FALSE)) -> custrecord_twc_ac_fac_svc
A19: F | B19: T | C19: OSSMTWC - Accommodation | D19: customrecord_twc_ac | E19: =VLOOKUP(D19,'TABLES SB'!D:D,1,FALSE) -> customrecord_twc_ac | F19: RECORD | G19: Check Box | I19: Fire Alarm Present | J19: custrecord_twc_ac_fire_alarm_pres | K19: =IF(J19="","",VLOOKUP(J19,SB!I:I,1,FALSE)) -> custrecord_twc_ac_fire_alarm_pres
A20: F | B20: T | C20: OSSMTWC - Accommodation | D20: customrecord_twc_ac | E20: =VLOOKUP(D20,'TABLES SB'!D:D,1,FALSE) -> customrecord_twc_ac | F20: RECORD | G20: Free-Form Text | I20: Height (m) | J20: custrecord_twc_ac_height | K20: =IF(J20="","",VLOOKUP(J20,SB!I:I,1,FALSE)) -> custrecord_twc_ac_height
A21: F | B21: T | C21: OSSMTWC - Accommodation | D21: customrecord_twc_ac | E21: =VLOOKUP(D21,'TABLES SB'!D:D,1,FALSE) -> customrecord_twc_ac | F21: RECORD | G21: Free-Form Text | I21: Infrastructure ID | J21: custrecord_twc_ac_infra_id | K21: =IF(J21="","",VLOOKUP(J21,SB!I:I,1,FALSE)) -> custrecord_twc_ac_infra_id
A22: F | B22: T | C22: OSSMTWC - Accommodation | D22: customrecord_twc_ac | E22: =VLOOKUP(D22,'TABLES SB'!D:D,1,FALSE) -> customrecord_twc_ac | F22: RECORD | G22: Date | I22: Installed | J22: custrecord_twc_ac_installed | K22: =IF(J22="","",VLOOKUP(J22,SB!I:I,1,FALSE)) -> custrecord_twc_ac_installed
A23: F | B23: T | C23: OSSMTWC - Accommodation | D23: customrecord_twc_ac | E23: =VLOOKUP(D23,'TABLES SB'!D:D,1,FALSE) -> customrecord_twc_ac | F23: RECORD | G23: Check Box | I23: Intruder Alarm Present | J23: custrecord_twc_ac_intruder_alarm_pres | K23: =IF(J23="","",VLOOKUP(J23,SB!I:I,1,FALSE)) -> custrecord_twc_ac_intruder_alarm_pres
A24: F | B24: T | C24: OSSMTWC - Accommodation | D24: customrecord_twc_ac | E24: =VLOOKUP(D24,'TABLES SB'!D:D,1,FALSE) -> customrecord_twc_ac | F24: RECORD | G24: Free-Form Text | I24: Intruder Code | J24: custrecord_twc_ac_intruder_code | K24: =IF(J24="","",VLOOKUP(J24,SB!I:I,1,FALSE)) -> custrecord_twc_ac_intruder_code
A25: F | B25: T | C25: OSSMTWC - Accommodation | D25: customrecord_twc_ac | E25: =VLOOKUP(D25,'TABLES SB'!D:D,1,FALSE) -> customrecord_twc_ac | F25: RECORD | G25: Free-Form Text | I25: Length (m) | J25: custrecord_twc_ac_length | K25: =IF(J25="","",VLOOKUP(J25,SB!I:I,1,FALSE)) -> custrecord_twc_ac_length
A26: F | B26: T | C26: OSSMTWC - Accommodation | D26: customrecord_twc_ac | E26: =VLOOKUP(D26,'TABLES SB'!D:D,1,FALSE) -> customrecord_twc_ac | F26: RECORD | G26: Integer Number | I26: Loadings | J26: custrecord_twc_ac_loadings | K26: =IF(J26="","",VLOOKUP(J26,SB!I:I,1,FALSE)) -> custrecord_twc_ac_loadings
A27: F | B27: T | C27: OSSMTWC - Accommodation | D27: customrecord_twc_ac | E27: =VLOOKUP(D27,'TABLES SB'!D:D,1,FALSE) -> customrecord_twc_ac | F27: RECORD | G27: List/Record | H27: 1106 | I27: Lock | J27: custrecord_twc_ac_lock | K27: =IF(J27="","",VLOOKUP(J27,SB!I:I,1,FALSE)) -> custrecord_twc_ac_lock
A28: F | B28: T | C28: OSSMTWC - Accommodation | D28: customrecord_twc_ac | E28: =VLOOKUP(D28,'TABLES SB'!D:D,1,FALSE) -> customrecord_twc_ac | F28: RECORD | G28: Free-Form Text | I28: Model | J28: custrecord_twc_ac_model | K28: =IF(J28="","",VLOOKUP(J28,SB!I:I,1,FALSE)) -> custrecord_twc_ac_model
A29: F | B29: T | C29: OSSMTWC - Accommodation | D29: customrecord_twc_ac | E29: =VLOOKUP(D29,'TABLES SB'!D:D,1,FALSE) -> customrecord_twc_ac | F29: RECORD | G29: Integer Number | I29: Noise Level | J29: custrecord_twc_ac_noice_level | K29: =IF(J29="","",VLOOKUP(J29,SB!I:I,1,FALSE)) -> custrecord_twc_ac_noice_level
A30: F | B30: T | C30: OSSMTWC - Accommodation | D30: customrecord_twc_ac | E30: =VLOOKUP(D30,'TABLES SB'!D:D,1,FALSE) -> customrecord_twc_ac | F30: RECORD | G30: Date | I30: Next Aircon Service | J30: custrecord_twc_ac_nxt_aircon_svc | K30: =IF(J30="","",VLOOKUP(J30,SB!I:I,1,FALSE)) -> custrecord_twc_ac_nxt_aircon_svc
A31: F | B31: T | C31: OSSMTWC - Accommodation | D31: customrecord_twc_ac | E31: =VLOOKUP(D31,'TABLES SB'!D:D,1,FALSE) -> customrecord_twc_ac | F31: RECORD | G31: Date | I31: Next Alarm Service | J31: custrecord_twc_ac_nxt_alarm_svc | K31: =IF(J31="","",VLOOKUP(J31,SB!I:I,1,FALSE)) -> custrecord_twc_ac_nxt_alarm_svc
A32: F | B32: T | C32: OSSMTWC - Accommodation | D32: customrecord_twc_ac | E32: =VLOOKUP(D32,'TABLES SB'!D:D,1,FALSE) -> customrecord_twc_ac | F32: RECORD | G32: Date | I32: Next Fire Service | J32: custrecord_twc_ac_nxt_fire_svc | K32: =IF(J32="","",VLOOKUP(J32,SB!I:I,1,FALSE)) -> custrecord_twc_ac_nxt_fire_svc
A33: F | B33: T | C33: OSSMTWC - Accommodation | D33: customrecord_twc_ac | E33: =VLOOKUP(D33,'TABLES SB'!D:D,1,FALSE) -> customrecord_twc_ac | F33: RECORD | G33: List/Record | H33: 1153 | I33: Public | J33: custrecord_twc_ac_public | K33: =IF(J33="","",VLOOKUP(J33,SB!I:I,1,FALSE)) -> custrecord_twc_ac_public
A34: F | B34: T | C34: OSSMTWC - Accommodation | D34: customrecord_twc_ac | E34: =VLOOKUP(D34,'TABLES SB'!D:D,1,FALSE) -> customrecord_twc_ac | F34: RECORD | G34: Integer Number | I34: Rack Spaces Available | J34: custrecord_twc_ac_rack_spaces_available | K34: =IF(J34="","",VLOOKUP(J34,SB!I:I,1,FALSE)) -> custrecord_twc_ac_rack_spaces_available
A35: F | B35: T | C35: OSSMTWC - Accommodation | D35: customrecord_twc_ac | E35: =VLOOKUP(D35,'TABLES SB'!D:D,1,FALSE) -> customrecord_twc_ac | F35: RECORD | G35: Check Box | I35: SAF Auto-Approve | J35: custrecord_twc_ac_saf_auto_approve | K35: =IF(J35="","",VLOOKUP(J35,SB!I:I,1,FALSE)) -> custrecord_twc_ac_saf_auto_approve
A36: F | B36: T | C36: OSSMTWC - Accommodation | D36: customrecord_twc_ac | E36: =VLOOKUP(D36,'TABLES SB'!D:D,1,FALSE) -> customrecord_twc_ac | F36: RECORD | G36: List/Record | H36: 1025 | I36: SAF Status | J36: custrecord_twc_ac_saf_sts | K36: =IF(J36="","",VLOOKUP(J36,SB!I:I,1,FALSE)) -> custrecord_twc_ac_saf_sts
A37: F | B37: T | C37: OSSMTWC - Accommodation | D37: customrecord_twc_ac | E37: =VLOOKUP(D37,'TABLES SB'!D:D,1,FALSE) -> customrecord_twc_ac | F37: RECORD | G37: List/Record | H37: 1148 | I37: Site | J37: custrecord_twc_ac_site | K37: =IF(J37="","",VLOOKUP(J37,SB!I:I,1,FALSE)) -> custrecord_twc_ac_site
A38: F | B38: T | C38: OSSMTWC - Accommodation | D38: customrecord_twc_ac | E38: =VLOOKUP(D38,'TABLES SB'!D:D,1,FALSE) -> customrecord_twc_ac | F38: RECORD | G38: List/Record | H38: 1026 | I38: SRF Status | J38: custrecord_twc_ac_srf_sts | K38: =IF(J38="","",VLOOKUP(J38,SB!I:I,1,FALSE)) -> custrecord_twc_ac_srf_sts
A39: F | B39: T | C39: OSSMTWC - Accommodation | D39: customrecord_twc_ac | E39: =VLOOKUP(D39,'TABLES SB'!D:D,1,FALSE) -> customrecord_twc_ac | F39: RECORD | G39: List/Record | H39: 1027 | I39: Accommodation Status | J39: custrecord_twc_ac_sts | K39: =IF(J39="","",VLOOKUP(J39,SB!I:I,1,FALSE)) -> custrecord_twc_ac_sts
A40: F | B40: T | C40: OSSMTWC - Accommodation | D40: customrecord_twc_ac | E40: =VLOOKUP(D40,'TABLES SB'!D:D,1,FALSE) -> customrecord_twc_ac | F40: RECORD | G40: List/Record | H40: 1028 | I40: Accommodation Type | J40: custrecord_twc_ac_type | K40: =IF(J40="","",VLOOKUP(J40,SB!I:I,1,FALSE)) -> custrecord_twc_ac_type
...

Sheet SB
A1: includename | B1: isinactive | C1: name | D1: record_id | E1: fieldtype | F1: fieldvaluetype | G1: fieldvaluetyperecord | H1: name_0 | I1: field_id
A2: T | B2: F | C2: OSSMTWC - Power Meter | D2: customrecordcustomrecord_twc_pwr_mtr | E2: RECORD | F2: Text Area | G2: null | H2: Meter Comment | I2: custrecord_twc_pwr_mtr_comm
A3: T | B3: F | C3: OSSMTWC - Power Meter | D3: customrecordcustomrecord_twc_pwr_mtr | E3: RECORD | F3: Free-Form Text | G3: null | H3: Power Meter ID | I3: custrecord_twc_pwr_mtr_id
A4: T | B4: F | C4: OSSMTWC - Power Meter | D4: customrecordcustomrecord_twc_pwr_mtr | E4: RECORD | F4: Integer Number | G4: null | H4: Latest Day Reading | I4: custrecord_twc_pwr_mtr_last_day_read
A5: T | B5: F | C5: OSSMTWC - Power Meter | D5: customrecordcustomrecord_twc_pwr_mtr | E5: RECORD | F5: Integer Number | G5: null | H5: Latest Night Reading | I5: custrecord_twc_pwr_mtr_last_night_read
A6: T | B6: F | C6: OSSMTWC - Power Meter | D6: customrecordcustomrecord_twc_pwr_mtr | E6: RECORD | F6: Integer Number | G6: null | H6: Latest Peak Reading | I6: custrecord_twc_pwr_mtr_last_peak_read
A7: T | B7: F | C7: OSSMTWC - Power Meter | D7: customrecordcustomrecord_twc_pwr_mtr | E7: RECORD | F7: Date | G7: null | H7: Latest Meter Reading Date | I7: custrecord_twc_pwr_mtr_last_read_date
A8: T | B8: F | C8: OSSMTWC - Power Meter | D8: customrecordcustomrecord_twc_pwr_mtr | E8: RECORD | F8: Decimal Number | G8: null | H8: Latest kWh Usage - Reading | I8: custrecord_twc_pwr_mtr_last_usage
A9: T | B9: F | C9: OSSMTWC - Power Meter | D9: customrecordcustomrecord_twc_pwr_mtr | E9: RECORD | F9: Decimal Number | G9: null | H9: Latest kWh Usage - Amp Check | I9: custrecord_twc_pwr_mtr_last_usage_amp
A10: T | B10: F | C10: OSSMTWC - Power Meter | D10: customrecordcustomrecord_twc_pwr_mtr | E10: RECORD | F10: Free-Form Text | G10: null | H10: Meter Location | I10: custrecord_twc_pwr_mtr_loc
A11: T | B11: F | C11: OSSMTWC - Power Meter | D11: customrecordcustomrecord_twc_pwr_mtr | E11: RECORD | F11: List/Record | G11: 1069 | H11: Meter Unit Multiplier | I11: custrecord_twc_pwr_mtr_mult
A12: T | B12: F | C12: OSSMTWC - Power Meter | D12: customrecordcustomrecord_twc_pwr_mtr | E12: RECORD | F12: Check Box | G12: null | H12: Power Supplier must read Meter | I12: custrecord_twc_pwr_mtr_mustread
A13: T | B13: F | C13: OSSMTWC - Power Meter | D13: customrecordcustomrecord_twc_pwr_mtr | E13: RECORD | F13: Free-Form Text | G13: null | H13: Meter Name | I13: custrecord_twc_pwr_mtr_name
A14: T | B14: F | C14: OSSMTWC - Power Meter | D14: customrecordcustomrecord_twc_pwr_mtr | E14: RECORD | F14: Free-Form Text | G14: null | H14: Meter Number | I14: custrecord_twc_pwr_mtr_num
A15: T | B15: F | C15: OSSMTWC - Power Meter | D15: customrecordcustomrecord_twc_pwr_mtr | E15: RECORD | F15: Date | G15: null | H15: Next Meter Reading Date | I15: custrecord_twc_pwr_mtr_nxt_read
A16: T | B16: F | C16: OSSMTWC - Power Meter | D16: customrecordcustomrecord_twc_pwr_mtr | E16: RECORD | F16: List/Record | G16: 830 | H16: Meter Power Phase | I16: custrecord_twc_pwr_mtr_phase
A17: T | B17: F | C17: OSSMTWC - Power Meter | D17: customrecordcustomrecord_twc_pwr_mtr | E17: RECORD | F17: Integer Number | G17: null | H17: Meter Reading Freq | I17: custrecord_twc_pwr_mtr_read_freq
A18: T | B18: F | C18: OSSMTWC - Power Meter | D18: customrecordcustomrecord_twc_pwr_mtr | E18: RECORD | F18: List/Record | G18: 718 | H18: Site | I18: custrecord_twc_pwr_mtr_site
A19: T | B19: F | C19: OSSMTWC - Power Meter | D19: customrecordcustomrecord_twc_pwr_mtr | E19: RECORD | F19: List/Record | G19: 676 | H19: Power Supply | I19: custrecord_twc_pwr_mtr_sply
A20: T | B20: F | C20: OSSMTWC - Power Meter | D20: customrecordcustomrecord_twc_pwr_mtr | E20: RECORD | F20: List/Record | G20: 1061 | H20: Meter Status | I20: custrecord_twc_pwr_mtr_sts
A21: T | B21: F | C21: OSSMTWC - Power Meter | D21: customrecordcustomrecord_twc_pwr_mtr | E21: RECORD | F21: Check Box | G21: null | H21: Supplier Informed | I21: custrecord_twc_pwr_mtr_supplier_informed
A22: T | B22: F | C22: OSSMTWC - Power Meter | D22: customrecordcustomrecord_twc_pwr_mtr | E22: RECORD | F22: List/Record | G22: 1065 | H22: Meter Type | I22: custrecord_twc_pwr_mtr_type
A23: T | B23: F | C23: OSSMTWC - AWL Type | D23: customrecord_ossm_twc_awl_type | E23: null | F23: null | G23: null | H23: null | I23: null
A24: T | B24: F | C24: OSSMTWC - FE Last Test Result | D24: customrecord_ossm_twc_fe_last_test_res | E24: null | F24: null | G24: null | H24: null | I24: null
A25: T | B25: F | C25: OSSMTWC - FE Type | D25: customrecord_ossm_twc_fe_type | E25: null | F25: null | G25: null | H25: null | I25: null
A26: T | B26: F | C26: OSSMTWC - FIRE EXTINGUISHER | D26: customrecord_ossm_twc_fire_extinguisher | E26: RECORD | F26: List/Record | G26: 815 | H26: Accommodation | I26: custrecord_twc_fe_acc
A27: T | B27: F | C27: OSSMTWC - FIRE EXTINGUISHER | D27: customrecord_ossm_twc_fire_extinguisher | E27: RECORD | F27: Text Area | G27: null | H27: Comments | I27: custrecord_twc_fe_comments
A28: T | B28: F | C28: OSSMTWC - FIRE EXTINGUISHER | D28: customrecord_ossm_twc_fire_extinguisher | E28: RECORD | F28: Free-Form Text | G28: null | H28: Fire Extinguisher ID | I28: custrecord_twc_fe_id
A29: T | B29: F | C29: OSSMTWC - FIRE EXTINGUISHER | D29: customrecord_ossm_twc_fire_extinguisher | E29: RECORD | F29: Date | G29: null | H29: Installed Date | I29: custrecord_twc_fe_inst_date
A30: T | B30: F | C30: OSSMTWC - FIRE EXTINGUISHER | D30: customrecord_ossm_twc_fire_extinguisher | E30: RECORD | F30: Date | G30: null | H30: Refill Date | I30: custrecord_twc_fe_refill_date
A31: T | B31: F | C31: OSSMTWC - FIRE EXTINGUISHER | D31: customrecord_ossm_twc_fire_extinguisher | E31: RECORD | F31: List/Record | G31: 718 | H31: Site | I31: custrecord_twc_fe_site
A32: T | B32: F | C32: OSSMTWC - FIRE EXTINGUISHER | D32: customrecord_ossm_twc_fire_extinguisher | E32: RECORD | F32: List/Record | G32: 1057 | H32: FE Status | I32: custrecord_twc_fe_status
A33: T | B33: F | C33: OSSMTWC - FIRE EXTINGUISHER | D33: customrecord_ossm_twc_fire_extinguisher | E33: RECORD | F33: List/Record | G33: 1058 | H33: FE Type | I33: custrecord_twc_fe_ty
A34: T | B34: F | C34: OSSMTWC - FIRE EXTINGUISHER | D34: customrecord_ossm_twc_fire_extinguisher | E34: RECORD | F34: Integer Number | G34: null | H34: Year of Manufacture | I34: custrecord_twc_fe_yom
A35: T | B35: F | C35: OSSMTWC - FIRE EXTINGUISHER | D35: customrecord_ossm_twc_fire_extinguisher | E35: RECORD | F35: List/Record | G35: 1059 | H35: Last Test Result | I35: custrecord_twc_last_test_res
A36: T | B36: F | C36: OSSMTWC - FIRE EXTINGUISHER | D36: customrecord_ossm_twc_fire_extinguisher | E36: RECORD | F36: Free-Form Text | G36: null | H36: Location | I36: custrecord_twc_location
A37: F | B37: T | C37: OSSMTWC - Accommodation | D37: customrecord_twc_ac | E37: RECORD | F37: List/Record | G37: 699 | H37: AC Feed Phase | I37: custrecord_twc_ac_ac_feed_phase
A38: F | B38: T | C38: OSSMTWC - Accommodation | D38: customrecord_twc_ac | E38: RECORD | F38: Free-Form Text | G38: null | H38: Comments | I38: custrecord_twc_ac_comments
A39: F | B39: T | C39: OSSMTWC - Accommodation | D39: customrecord_twc_ac | E39: RECORD | F39: List/Record | G39: 688 | H39: Facilities Services | I39: custrecord_twc_ac_fac_svc
A40: F | B40: T | C40: OSSMTWC - Accommodation | D40: customrecord_twc_ac | E40: RECORD | F40: Check Box | G40: null | H40: Fire Alarm Present | I40: custrecord_twc_ac_fire_alarm_pres
...

Sheet TABLES LIVE
A1: includename | B1: isinactive | C1: name | D1: record_id | E1: IN SB
A2: T | B2: F | C2: OSSM TWC - A/C Unit Status | D2: customrecord_twc_ac_unit_status | E2: =VLOOKUP(D2,'TABLES SB'!D:D,1,FALSE) -> customrecord_twc_ac_unit_status
A3: T | B3: F | C3: OSSMTWC - A/C Model | D3: customrecord_twc_ac_model | E3: =VLOOKUP(D3,'TABLES SB'!D:D,1,FALSE) -> customrecord_twc_ac_model
A4: T | B4: F | C4: OSSMTWC - A/C System Refrigerant | D4: customrecord_twc_sys_refrig | E4: =VLOOKUP(D4,'TABLES SB'!D:D,1,FALSE) -> customrecord_twc_sys_refrig
A5: T | B5: F | C5: OSSMTWC - A/C Units | D5: customrecord_twc_ac_unit | E5: =VLOOKUP(D5,'TABLES SB'!D:D,1,FALSE) -> customrecord_twc_ac_unit
A6: T | B6: F | C6: OSSMTWC - AC Feed Phase | D6: customrecord_twc_ac_feed_phase | E6: =VLOOKUP(D6,'TABLES SB'!D:D,1,FALSE) -> customrecord_twc_ac_feed_phase
A7: F | B7: F | C7: OSSMTWC - ACL | D7: customrecord_twc_acl | E7: =VLOOKUP(D7,'TABLES SB'!D:D,1,FALSE) -> customrecord_twc_acl
A8: F | B8: F | C8: OSSMTWC - ASCL | D8: customrecord_twc_ascl | E8: =VLOOKUP(D8,'TABLES SB'!D:D,1,FALSE) -> customrecord_twc_ascl
A9: F | B9: F | C9: OSSMTWC - AWL | D9: customrecord_twc_awl | E9: =VLOOKUP(D9,'TABLES SB'!D:D,1,FALSE) -> customrecord_twc_awl
A10: T | B10: F | C10: OSSMTWC - AWL Intensity | D10: customrecord_twc_awl_intensity | E10: =VLOOKUP(D10,'TABLES SB'!D:D,1,FALSE) -> customrecord_twc_awl_intensity
A11: T | B11: F | C11: OSSMTWC - AWL Type | D11: customrecord_ossm_twc_awl_type | E11: =VLOOKUP(D11,'TABLES SB'!D:D,1,FALSE) -> customrecord_ossm_twc_awl_type
A12: F | B12: T | C12: OSSMTWC - Accommodation | D12: customrecord_twc_ac | E12: =VLOOKUP(D12,'TABLES SB'!D:D,1,FALSE) -> customrecord_twc_ac
A13: T | B13: T | C13: OSSMTWC - Accommodation SAF Status | D13: customrecord_twc_accom_saf_sts | E13: =VLOOKUP(D13,'TABLES SB'!D:D,1,FALSE) -> customrecord_twc_accom_saf_sts
... A191: F | B191: F | C191: TWC - Issue List | D191: customrecord_twc_issue | E191: =VLOOKUP(D191,'TABLES SB'!D:D,1,FALSE) -> customrecord_twc_issue

Sheet TABLES SB
A1: includename | B1: isinactive | C1: name | D1: record_id | E1: IN LIVE
A2: T | B2: F | C2: OSSM TWC - A/C Unit Status | D2: customrecord_twc_ac_unit_status | E2: =VLOOKUP(D2,'TABLES LIVE'!D:D,1,FALSE) -> customrecord_twc_ac_unit_status
A3: T | B3: F | C3: OSSMTWC - A/C Model | D3: customrecord_twc_ac_model | E3: =VLOOKUP(D3,'TABLES LIVE'!D:D,1,FALSE) -> customrecord_twc_ac_model
A4: T | B4: F | C4: OSSMTWC - A/C System Refrigerant | D4: customrecord_twc_sys_refrig | E4: =VLOOKUP(D4,'TABLES LIVE'!D:D,1,FALSE) -> customrecord_twc_sys_refrig
A5: T | B5: F | C5: OSSMTWC - A/C Units | D5: customrecord_twc_ac_unit | E5: =VLOOKUP(D5,'TABLES LIVE'!D:D,1,FALSE) -> customrecord_twc_ac_unit
A6: T | B6: F | C6: OSSMTWC - AC Feed Phase | D6: customrecord_twc_ac_feed_phase | E6: =VLOOKUP(D6,'TABLES LIVE'!D:D,1,FALSE) -> customrecord_twc_ac_feed_phase
A7: F | B7: F | C7: OSSMTWC - ACL | D7: customrecord_twc_acl | E7: =VLOOKUP(D7,'TABLES LIVE'!D:D,1,FALSE) -> customrecord_twc_acl
A8: F | B8: F | C8: OSSMTWC - ASCL | D8: customrecord_twc_ascl | E8: =VLOOKUP(D8,'TABLES LIVE'!D:D,1,FALSE) -> customrecord_twc_ascl
A9: F | B9: F | C9: OSSMTWC - AWL | D9: customrecord_twc_awl | E9: =VLOOKUP(D9,'TABLES LIVE'!D:D,1,FALSE) -> customrecord_twc_awl
A10: T | B10: F | C10: OSSMTWC - AWL Intensity | D10: customrecord_twc_awl_intensity | E10: =VLOOKUP(D10,'TABLES LIVE'!D:D,1,FALSE) -> customrecord_twc_awl_intensity
A11: T | B11: F | C11: OSSMTWC - AWL Type | D11: customrecord_ossm_twc_awl_type | E11: =VLOOKUP(D11,'TABLES LIVE'!D:D,1,FALSE) -> customrecord_ossm_twc_awl_type
A12: F | B12: T | C12: OSSMTWC - Accommodation | D12: customrecord_twc_ac | E12: =VLOOKUP(D12,'TABLES LIVE'!D:D,1,FALSE) -> customrecord_twc_ac
A13: T | B13: T | C13: OSSMTWC - Accommodation SAF Status | D13: customrecord_twc_accom_saf_sts | E13: =VLOOKUP(D13,'TABLES LIVE'!D:D,1,FALSE) -> customrecord_twc_accom_saf_sts
... A58: F | B58: F | C58: OSSMTWC - Feeder | D58: customrecord_twc_fd | E58: =VLOOKUP(D58,'TABLES LIVE'!D:D,1,FALSE) -> customrecord_twc_fd
A59: F | B59: F | C59: OSSMTWC - Field Access Configs | D59: customrecord_twc_fieldaccess | E59: =VLOOKUP(D59,'TABLES LIVE'!D:D,1,FALSE) -> #N/A | F59: FIXED
A60: T | B60: F | C60: OSSMTWC - File | D60: customrecord_twc_file | E60: =VLOOKUP(D60,'TABLES LIVE'!D:D,1,FALSE) -> customrecord_twc_file
A61: T | B61: F | C61: OSSMTWC - File Status | D61: customrecord_twc_file_status | E61: =VLOOKUP(D61,'TABLES LIVE'!D:D,1,FALSE) -> customrecord_twc_file_status
A62: T | B62: F | C62: OSSMTWC - File Type | D62: customrecord_twc_file_type | E62: =VLOOKUP(D62,'TABLES LIVE'!D:D,1,FALSE) -> customrecord_twc_file_type
A63: T | B63: F | C63: OSSMTWC - Financial Condition Status | D63: customrecord_twc_financial_condition_sts | E63: =VLOOKUP(D63,'TABLES LIVE'!D:D,1,FALSE) -> customrecord_twc_financial_condition_sts
A64: F | B64: T | C64: OSSMTWC - Generator | D64: customrecord_twc_gen | E64: =VLOOKUP(D64,'TABLES LIVE'!D:D,1,FALSE) -> customrecord_twc_gen
A65: F | B65: F | C65: OSSMTWC - Generator Service | D65: customrecord_twc_gen_svc | E65: =VLOOKUP(D65,'TABLES LIVE'!D:D,1,FALSE) -> customrecord_twc_gen_svc
A66: T | B66: F | C66: OSSMTWC - Generator Service Type | D66: customrecord_twc_gen_svc_type | E66: =VLOOKUP(D66,'TABLES LIVE'!D:D,1,FALSE) -> customrecord_twc_gen_svc_type
A67: T | B67: T | C67: OSSMTWC - Generator Status | D67: customrecord_twc_gen_sts | E67: =VLOOKUP(D67,'TABLES LIVE'!D:D,1,FALSE) -> customrecord_twc_gen_sts
A68: T | B68: F | C68: OSSMTWC - Infra AC Feed Phase | D68: customrecord_twc_infra_ac_feed_phase | E68: =VLOOKUP(D68,'TABLES LIVE'!D:D,1,FALSE) -> customrecord_twc_infra_ac_feed_phase
A69: T | B69: F | C69: OSSMTWC - Infra Accommodation Type | D69: customrecord_twc_infra_accom | E69: =VLOOKUP(D69,'TABLES LIVE'!D:D,1,FALSE) -> customrecord_twc_infra_accom
A70: T | B70: F | C70: OSSMTWC - Infra Fall Arrest Status | D70: customrecord_twc_infra_fall_arr_sts | E70: =VLOOKUP(D70,'TABLES LIVE'!D:D,1,FALSE) -> customrecord_twc_infra_fall_arr_sts
A71: T | B71: F | C71: OSSMTWC - Infra Fall Arrest Types | D71: customrecord_twc_infra_fall_arr_types | E71: =VLOOKUP(D71,'TABLES LIVE'!D:D,1,FALSE) -> customrecord_twc_infra_fall_arr_types
... A167: T | B167: F | C167: OSSMTWC - SRF Item Voltage Type | D167: customrecord_twc_srf_itm_v_type | E167: =VLOOKUP(D167,'TABLES LIVE'!D:D,1,FALSE) -> customrecord_twc_srf_itm_v_type
A168: T | B168: F | C168: OSSMTWC - SRF Revenue Impact | D168: customrecord_twc_srf_revenue_impact | E168: =VLOOKUP(D168,'TABLES LIVE'!D:D,1,FALSE) -> #N/A | F168: FIXED
A169: T | B169: F | C169: OSSMTWC - SRF Review | D169: customrecord_twc_srf_rev | E169: =VLOOKUP(D169,'TABLES LIVE'!D:D,1,FALSE) -> customrecord_twc_srf_rev
A170: T | B170: F | C170: OSSMTWC - SRF Status | D170: customrecord_twc_srf_status | E170: =VLOOKUP(D170,'TABLES LIVE'!D:D,1,FALSE) -> customrecord_twc_srf_status
A171: T | B171: F | C171: OSSMTWC - SRF Type | D171: customrecord_twc_srf_type | E171: =VLOOKUP(D171,'TABLES LIVE'!D:D,1,FALSE) -> customrecord_twc_srf_type
A172: T | B172: F | C172: OSSMTWC - SRF Workflow | D172: customrecord_twc_srf_wkf | E172: =VLOOKUP(D172,'TABLES LIVE'!D:D,1,FALSE) -> customrecord_twc_srf_wkf
A173: F | B173: F | C173: OSSMTWC - SRF Workflow Item | D173: customrecord_twc_srf_wkfi | E173: =VLOOKUP(D173,'TABLES LIVE'!D:D,1,FALSE) -> customrecord_twc_srf_wkfi
A174: T | B174: F | C174: OSSMTWC - SRF Workflow Stage | D174: customrecord_twc_srf_wks | E174: =VLOOKUP(D174,'TABLES LIVE'!D:D,1,FALSE) -> customrecord_twc_srf_wks
A175: T | B175: F | C175: OSSMTWC - SRF Workflow Status | D175: customrecord_twc_srf_wkf_status | E175: =VLOOKUP(D175,'TABLES LIVE'!D:D,1,FALSE) -> customrecord_twc_srf_wkf_status
A176: T | B176: F | C176: OSSMTWC - Section 5 Decision | D176: customrecord_twc_section_5_decision | E176: =VLOOKUP(D176,'TABLES LIVE'!D:D,1,FALSE) -> customrecord_twc_section_5_decision
A177: T | B177: F | C177: OSSMTWC - Site | D177: customrecord_twc_site | E177: =VLOOKUP(D177,'TABLES LIVE'!D:D,1,FALSE) -> customrecord_twc_site
A178: T | B178: F | C178: OSSMTWC - Site BTS Status | D178: customrecord_twc_site_bts_sts | E178: =VLOOKUP(D178,'TABLES LIVE'!D:D,1,FALSE) -> customrecord_twc_site_bts_sts
A179: T | B179: F | C179: OSSMTWC - Site Level | D179: customrecord_twc_site_level | E179: =VLOOKUP(D179,'TABLES LIVE'!D:D,1,FALSE) -> customrecord_twc_site_level
...
