Workbook
Name Short_Code: #REF!
Name Status: #REF!
Name Short_Code: #REF!
Name Status: #REF!
Name Short_Code: #REF!
Name Status: #REF!

Sheet SITE Fields
A1: SITE Field Name | B1: NS Fields ID | C1: NS Field Type | D1: NS Action | F1: Data Source | G1: AREA | H1: SUB-AREA(S) | I1: Field Type | J1: Option Values | K1: Query / Comments
A2: RADIX Site Table entry number | B2: =VLOOKUP(A2,'SITE Fields NS'!B:C,2,FALSE) -> custrecord_twc_site_radix_tbl_entry_no | C2: =VLOOKUP(B2,'SITE Fields NS'!C:E,3,FALSE) -> Integer Number | F2: RADIX | G2: Summary | H2: Basic Information | I2: Integer
A3: Site ID | B3: =VLOOKUP(A3,'SITE Fields NS'!B:C,2,FALSE) -> custrecord_twc_site_id | C3: =VLOOKUP(B3,'SITE Fields NS'!C:E,3,FALSE) -> Free-Form Text | F3: MASTER TRACKER | G3: Summary | H3: Basic Information | I3: 8-character alphanumeric string | J3: -
A4: Site Name | B4: =VLOOKUP(A4,'SITE Fields NS'!B:C,2,FALSE) -> custrecord_twc_site_name | C4: =VLOOKUP(B4,'SITE Fields NS'!C:E,3,FALSE) -> Free-Form Text | F4: MASTER TRACKER | G4: Summary | H4: Basic Information | I4: Free-Form Text | J4: - | K4: -
A5: Alias | B5: =VLOOKUP(A5,'SITE Fields NS'!B:C,2,FALSE) -> custrecord_twc_site_alias | C5: =VLOOKUP(B5,'SITE Fields NS'!C:E,3,FALSE) -> Free-Form Text | F5: RADIX | G5: Summary | H5: Basic Information | I5: Free-Form Text | J5: - | K5: -
A6: Site Status | B6: =VLOOKUP(A6,'SITE Fields NS'!B:C,2,FALSE) -> custrecord_twc_site_status | C6: =VLOOKUP(B6,'SITE Fields NS'!C:E,3,FALSE) -> List/Record | F6: MASTER TRACKER | G6: Summary | H6: Basic Information | I6: Option | J6: Active, Option, Retired, To Be Retired, UTS | K6: -
A7: Site Type | B7: =VLOOKUP(A7,'SITE Fields NS'!B:C,2,FALSE) -> custrecord_twc_site_type | C7: =VLOOKUP(B7,'SITE Fields NS'!C:E,3,FALSE) -> List/Record | F7: MASTER TRACKER | G7: Summary | H7: Basic Information | I7: Option | J7: Greenfield, Rooftop, Colocation | K7: -
A8: Multi Mast Sites | B8: =VLOOKUP(A8,'SITE Fields NS'!B:C,2,FALSE) -> custrecord_twc_site_multi_mast_sites | C8: =VLOOKUP(B8,'SITE Fields NS'!C:E,3,FALSE) -> Check Box | F8: MASTER TRACKER | G8: Summary | H8: Basic Information | I8: Option | J8: Yes, No | K8: -
A9: Old ID | B9: =VLOOKUP(A9,'SITE Fields NS'!B:C,2,FALSE) -> custrecord_twc_site_old_id | C9: =VLOOKUP(B9,'SITE Fields NS'!C:E,3,FALSE) -> Free-Form Text | F9: MASTER TRACKER | G9: Summary | H9: Basic Information | I9: Free-Form Text | J9: - | K9: -
A10: Structures List | B10: =VLOOKUP(A10,'SITE Fields NS'!B:C,2,FALSE) -> #N/A | C10: =VLOOKUP(B10,'SITE Fields NS'!C:E,3,FALSE) -> #N/A | D10: REMOVE / IGNORE (this is a one-to-many) | F10: n/a | G10: Summary | H10: Infrastructure | I10: List of associated INFRASTRUCTURE records | J10: - | K10: List INFRASTRUCTURE Table entries with Site field matching and Infrastructure Type of Structure
A11: Accommodation List | B11: =VLOOKUP(A11,'SITE Fields NS'!B:C,2,FALSE) -> #N/A | C11: =VLOOKUP(B11,'SITE Fields NS'!C:E,3,FALSE) -> #N/A | D11: REMOVE / IGNORE (this is a one-to-many) | F11: n/a | G11: Summary | H11: Infrastructure | I11: List of associated INFRASTRUCTURE records | J11: - | K11: List INFRASTRUCTURE Table entries with Site field matching and Infrastructure Type of Accommodation
A12: Fibre List | B12: =VLOOKUP(A12,'SITE Fields NS'!B:C,2,FALSE) -> #N/A | C12: =VLOOKUP(B12,'SITE Fields NS'!C:E,3,FALSE) -> #N/A | D12: REMOVE / IGNORE (this is a one-to-many) | F12: n/a | G12: Summary | H12: Infrastructure | I12: List of associated INFRASTRUCTURE records | J12: - | K12: List INFRASTRUCTURE Table entries with Site field matching and Infrastructure Type of Fibre
A13: Height ASL (m) | B13: =VLOOKUP(A13,'SITE Fields NS'!B:C,2,FALSE) -> custrecord_twc_site_height_asl | C13: =VLOOKUP(B13,'SITE Fields NS'!C:E,3,FALSE) -> Decimal Number | F13: TLM TRACKER | G13: Summary | H13: Basic Information | I13: Decimal (2 decimal points) | J13: - | K13: -
A14: Site Level | B14: =VLOOKUP(A14,'SITE Fields NS'!B:C,2,FALSE) -> custrecord_twc_site_level | C14: =VLOOKUP(B14,'SITE Fields NS'!C:E,3,FALSE) -> List/Record | F14: RADIX | G14: Summary | H14: Basic Information | I14: Option | J14: Premium, Level 1, Level 2, Level 3, Level 4 | K14: -
A15: Portfolio | B15: =VLOOKUP(A15,'SITE Fields NS'!B:C,2,FALSE) -> custrecord_twc_site_portfolio | C15: =VLOOKUP(B15,'SITE Fields NS'!C:E,3,FALSE) -> List/Record | F15: MASTER TRACKER | G15: Summary | H15: Basic Information | I15: Option | J15: 108, TC68, EED, BTS, Other | K15: Option values updated
A16: SRF Status | B16: =VLOOKUP(A16,'SITE Fields NS'!B:C,2,FALSE) -> custrecord_twc_site_srf_status | C16: =VLOOKUP(B16,'SITE Fields NS'!C:E,3,FALSE) -> List/Record | E16: This should not apply to single site but to the SRF record | F16: Master Tracker | G16: Structure | H16: General | I16: Option | J16: Full SRF, Remove Only, No SRF | K16: -
A17: SAF Status | B17: =VLOOKUP(A17,'SITE Fields NS'!B:C,2,FALSE) -> custrecord_twc_site_saf_status | C17: =VLOOKUP(B17,'SITE Fields NS'!C:E,3,FALSE) -> List/Record | E17: This should not apply to single site but to the SAF record | F17: Master Tracker | G17: Structure | H17: General | I17: Option | J17: Full SAF, Survey only, Op Maintenance only, Construction only, TL only, No SAF
A18: Public | B18: =VLOOKUP(A18,'SITE Fields NS'!B:C,2,FALSE) -> custrecord_twc_site_public | C18: =VLOOKUP(B18,'SITE Fields NS'!C:E,3,FALSE) -> List/Record | F18: MASTER TRACKER | G18: Summary | H18: Basic Information | I18: Option | J18: Yes All, Tenant Customer only, TL only, No All. | K18: -
A19: BTS Status | B19: =VLOOKUP(A19,'SITE Fields NS'!B:C,2,FALSE) -> custrecord_twc_site_bts_status | C19: =VLOOKUP(B19,'SITE Fields NS'!C:E,3,FALSE) -> List/Record | F19: MASTER TRACKER | G19: Summary | H19: Basic Information | I19: Option | J19: Option, Candidate, HOTs Signed, In Planning, Planning Granted, Acquired, In Build, Active
A20: Address | B20: =VLOOKUP(A20,'SITE Fields NS'!B:C,2,FALSE) -> custrecord_twc_site_address | C20: =VLOOKUP(B20,'SITE Fields NS'!C:E,3,FALSE) -> Free-Form Text | F20: RADIX | G20: Summary | H20: Location | I20: Free-Form Text | J20: - | K20: Does Netsuite have an address type?
A21: Eircode | B21: =VLOOKUP(A21,'SITE Fields NS'!B:C,2,FALSE) -> custrecord_twc_site_address_zip | C21: =VLOOKUP(B21,'SITE Fields NS'!C:E,3,FALSE) -> Free-Form Text | F21: NO SOURCE | G21: Summary | H21: Location | I21: Free-Form Text | J21: - | K21: NEW FIELD
A22: What3Words | B22: =VLOOKUP(A22,'SITE Fields NS'!B:C,2,FALSE) -> custrecord_twc_site_what3words | C22: =VLOOKUP(B22,'SITE Fields NS'!C:E,3,FALSE) -> Free-Form Text | F22: NO SOURCE | G22: Summary | H22: Location | I22: Free-Form Text | J22: -
A23: County | B23: =VLOOKUP(A23,'SITE Fields NS'!B:C,2,FALSE) -> custrecord_twc_site_address_county | C23: =VLOOKUP(B23,'SITE Fields NS'!C:E,3,FALSE) -> List/Record | F23: RADIX | G23: Summary | H23: Location | I23: Option | J23: - | K23: -
A24: Easting | B24: =VLOOKUP(A24,'SITE Fields NS'!B:C,2,FALSE) -> custrecord_twc_site_easting | C24: =VLOOKUP(B24,'SITE Fields NS'!C:E,3,FALSE) -> Decimal Number | F24: RADIX | G24: Summary | H24: Location | I24: 6-digit Decimal (0 decimal points) | J24: - | K24: Is one set calculated from the other or are each set independent? Is any validation done? Should we have separate coordinates for each STRUCTURE as well as a set of SITE coordinates?
A25: Northing | B25: =VLOOKUP(A25,'SITE Fields NS'!B:C,2,FALSE) -> custrecord_twc_site_northing | C25: =VLOOKUP(B25,'SITE Fields NS'!C:E,3,FALSE) -> Decimal Number | F25: RADIX | G25: Summary | H25: Location | I25: 6-digit Decimal (0 decimal points) | J25: -
A26: Longitude | B26: =VLOOKUP(A26,'SITE Fields NS'!B:C,2,FALSE) -> custrecord_twc_site_longitude | C26: =VLOOKUP(B26,'SITE Fields NS'!C:E,3,FALSE) -> Decimal Number | F26: RADIX | G26: Summary | H26: Location | I26: Decimal (6 decimal points) | J26: -
A27: Latitude | B27: =VLOOKUP(A27,'SITE Fields NS'!B:C,2,FALSE) -> custrecord_twc_site_latitude | C27: =VLOOKUP(B27,'SITE Fields NS'!C:E,3,FALSE) -> Decimal Number | F27: RADIX | G27: Summary | H27: Location | I27: Decimal (6 decimal points) | J27: -
A28: SAF Auto Approve | B28: =VLOOKUP(A28,'SITE Fields NS'!B:C,2,FALSE) -> custrecord_twc_site_saf_auto_approve | C28: =VLOOKUP(B28,'SITE Fields NS'!C:E,3,FALSE) -> Check Box | F28: RADIX | G28: Summary | H28: Access | I28: Option | J28: No, Yes | K28: -
A29: Track Type | B29: =VLOOKUP(A29,'SITE Fields NS'!B:C,2,FALSE) -> custrecord_twc_site_track_type | C29: =VLOOKUP(B29,'SITE Fields NS'!C:E,3,FALSE) -> List/Record | F29: RADIX | G29: Access | H29: Access | I29: Option | J29: Tarmac, Hardcore | K29: -
A30: Easting (Access) | B30: =VLOOKUP(A30,'SITE Fields NS'!B:C,2,FALSE) -> custrecord_twc_site_easting_access | C30: =VLOOKUP(B30,'SITE Fields NS'!C:E,3,FALSE) -> Decimal Number | F30: RADIX | G30: Access | H30: Access | I30: 6-digit Decimal (0 decimal points) | J30: - | K30: -
A31: Northing (Access) | B31: =VLOOKUP(A31,'SITE Fields NS'!B:C,2,FALSE) -> custrecord_twc_site_northing_access | C31: =VLOOKUP(B31,'SITE Fields NS'!C:E,3,FALSE) -> Decimal Number | F31: RADIX | G31: Access | H31: Access | I31: 6-digit Decimal (0 decimal points) | J31: - | K31: -
A32: Longitude (Access) | B32: =VLOOKUP(A32,'SITE Fields NS'!B:C,2,FALSE) -> custrecord_twc_site_longitude_access | C32: =VLOOKUP(B32,'SITE Fields NS'!C:E,3,FALSE) -> Decimal Number | F32: RADIX | G32: Access | H32: Access | I32: Decimal (6 decimal points) | J32: - | K32: -
A33: Latitude (Access) | B33: =VLOOKUP(A33,'SITE Fields NS'!B:C,2,FALSE) -> custrecord_twc_site_latitude_access | C33: =VLOOKUP(B33,'SITE Fields NS'!C:E,3,FALSE) -> Decimal Number | F33: RADIX | G33: Access | H33: Access | I33: Decimal (6 decimal points) | J33: - | K33: -
A34: Access What3Words | B34: =VLOOKUP(A34,'SITE Fields NS'!B:C,2,FALSE) -> custrecord_twc_site_acc_wt3words | C34: =VLOOKUP(B34,'SITE Fields NS'!C:E,3,FALSE) -> Free-Form Text | F34: NO SOURCE | G34: Access | H34: Access | I34: Free-Form Text | J34: -
A35: Directions | B35: =VLOOKUP(A35,'SITE Fields NS'!B:C,2,FALSE) -> custrecord_twc_site_directions | C35: =VLOOKUP(B35,'SITE Fields NS'!C:E,3,FALSE) -> Long Text | F35: RADIX | G35: Access | H35: Access | I35: Text Area | J35: - | K35: -
A36: Instructions | B36: =VLOOKUP(A36,'SITE Fields NS'!B:C,2,FALSE) -> custrecord_twc_site_instructions | C36: =VLOOKUP(B36,'SITE Fields NS'!C:E,3,FALSE) -> Long Text | F36: RADIX | G36: Access | H36: Access | I36: Text Area | J36: - | K36: -
A37: Tenant Card Required | B37: =VLOOKUP(A37,'SITE Fields NS'!B:C,2,FALSE) -> custrecord_twc_site_tenant_card_req | C37: =VLOOKUP(B37,'SITE Fields NS'!C:E,3,FALSE) -> Check Box | F37: RADIX | G37: Access | H37: Access | I37: Option | J37: No, Yes | K37: -
A38: 4x4 Required | B38: =VLOOKUP(A38,'SITE Fields NS'!B:C,2,FALSE) -> custrecord_twc_site_4x4_req | C38: =VLOOKUP(B38,'SITE Fields NS'!C:E,3,FALSE) -> Check Box | F38: RADIX | G38: Access | H38: Access | I38: Option | J38: No, Yes | K38: -
A39: Parking Restrictions | B39: =VLOOKUP(A39,'SITE Fields NS'!B:C,2,FALSE) -> custrecord_twc_site_parking_restr | C39: =VLOOKUP(B39,'SITE Fields NS'!C:E,3,FALSE) -> Free-Form Text | F39: RADIX | G39: Access | H39: Access | I39: Free-Form Text | J39: - | K39: -
A40: Crane/Mewp Access | B40: =VLOOKUP(A40,'SITE Fields NS'!B:C,2,FALSE) -> custrecord_twc_site_crane_mewp_access | C40: =VLOOKUP(B40,'SITE Fields NS'!C:E,3,FALSE) -> Check Box | F40: RADIX | G40: Access | H40: Access | I40: Option | J40: No, Yes | K40: -
...

Sheet SITE Fields NS
A1: Site Field | B1: name | C1: field_id | D1: fieldtype | E1: fieldvaluetype | F1: fieldvaluetyperecord
A2: =VLOOKUP(B2,'SITE Fields'!A:A,1,FALSE) -> RADIX Site Table entry number | B2: RADIX Site Table entry number | C2: custrecord_twc_site_radix_tbl_entry_no | D2: RECORD | E2: Integer Number | F2: null
A3: =VLOOKUP(B3,'SITE Fields'!A:A,1,FALSE) -> Site ID | B3: Site ID | C3: custrecord_twc_site_id | D3: RECORD | E3: Free-Form Text | F3: null
A4: =VLOOKUP(B4,'SITE Fields'!A:A,1,FALSE) -> Site Name | B4: Site Name | C4: custrecord_twc_site_name | D4: RECORD | E4: Free-Form Text | F4: null
A5: =VLOOKUP(B5,'SITE Fields'!A:A,1,FALSE) -> Alias | B5: Alias | C5: custrecord_twc_site_alias | D5: RECORD | E5: Free-Form Text | F5: null
A6: =VLOOKUP(B6,'SITE Fields'!A:A,1,FALSE) -> Site Status | B6: Site Status | C6: custrecord_twc_site_status | D6: RECORD | E6: List/Record | F6: 710
A7: =VLOOKUP(B7,'SITE Fields'!A:A,1,FALSE) -> Site Type | B7: Site Type | C7: custrecord_twc_site_type | D7: RECORD | E7: List/Record | F7: 712
A8: =VLOOKUP(B8,'SITE Fields'!A:A,1,FALSE) -> Multi Mast Sites | B8: Multi Mast Sites | C8: custrecord_twc_site_multi_mast_sites | D8: RECORD | E8: Check Box | F8: null
A9: =VLOOKUP(B9,'SITE Fields'!A:A,1,FALSE) -> Old ID | B9: Old ID | C9: custrecord_twc_site_old_id | D9: RECORD | E9: Free-Form Text | F9: null
A10: =VLOOKUP(B10,'SITE Fields'!A:A,1,FALSE) -> Height ASL (m) | B10: Height ASL (m) | C10: custrecord_twc_site_height_asl | D10: RECORD | E10: Decimal Number | F10: null
A11: =VLOOKUP(B11,'SITE Fields'!A:A,1,FALSE) -> Site Level | B11: Site Level | C11: custrecord_twc_site_level | D11: RECORD | E11: List/Record | F11: 713
A12: =VLOOKUP(B12,'SITE Fields'!A:A,1,FALSE) -> Portfolio | B12: Portfolio | C12: custrecord_twc_site_portfolio | D12: RECORD | E12: List/Record | F12: 714
A13: =VLOOKUP(B13,'SITE Fields'!A:A,1,FALSE) -> SRF Status | B13: SRF Status | C13: custrecord_twc_site_srf_status | D13: RECORD | E13: List/Record | F13: 697
A14: =VLOOKUP(B14,'SITE Fields'!A:A,1,FALSE) -> SAF Status | B14: SAF Status | C14: custrecord_twc_site_saf_status | D14: RECORD | E14: List/Record | F14: 698
A15: =VLOOKUP(B15,'SITE Fields'!A:A,1,FALSE) -> Public | B15: Public | C15: custrecord_twc_site_public | D15: RECORD | E15: List/Record | F15: 684
A16: =VLOOKUP(B16,'SITE Fields'!A:A,1,FALSE) -> BTS Status | B16: BTS Status | C16: custrecord_twc_site_bts_status | D16: RECORD | E16: List/Record | F16: 715
A17: =VLOOKUP(B17,'SITE Fields'!A:A,1,FALSE) -> Address | B17: Address | C17: custrecord_twc_site_address | D17: RECORD | E17: Free-Form Text | F17: null
A18: =VLOOKUP(B18,'SITE Fields'!A:A,1,FALSE) -> Easting | B18: Easting | C18: custrecord_twc_site_easting | D18: RECORD | E18: Decimal Number | F18: null
A19: =VLOOKUP(B19,'SITE Fields'!A:A,1,FALSE) -> Northing | B19: Northing | C19: custrecord_twc_site_northing | D19: RECORD | E19: Decimal Number | F19: null
A20: =VLOOKUP(B20,'SITE Fields'!A:A,1,FALSE) -> Longitude | B20: Longitude | C20: custrecord_twc_site_longitude | D20: RECORD | E20: Decimal Number | F20: null
A21: =VLOOKUP(B21,'SITE Fields'!A:A,1,FALSE) -> Latitude | B21: Latitude | C21: custrecord_twc_site_latitude | D21: RECORD | E21: Decimal Number | F21: null
A22: =VLOOKUP(B22,'SITE Fields'!A:A,1,FALSE) -> SAF Auto Approve | B22: SAF Auto Approve | C22: custrecord_twc_site_saf_auto_approve | D22: RECORD | E22: Check Box | F22: null
A23: =VLOOKUP(B23,'SITE Fields'!A:A,1,FALSE) -> Track Type | B23: Track Type | C23: custrecord_twc_site_track_type | D23: RECORD | E23: List/Record | F23: 716
A24: =VLOOKUP(B24,'SITE Fields'!A:A,1,FALSE) -> Easting (Access) | B24: Easting (Access) | C24: custrecord_twc_site_easting_access | D24: RECORD | E24: Decimal Number | F24: null
A25: =VLOOKUP(B25,'SITE Fields'!A:A,1,FALSE) -> Northing (Access) | B25: Northing (Access) | C25: custrecord_twc_site_northing_access | D25: RECORD | E25: Decimal Number | F25: null
A26: =VLOOKUP(B26,'SITE Fields'!A:A,1,FALSE) -> Longitude (Access) | B26: Longitude (Access) | C26: custrecord_twc_site_longitude_access | D26: RECORD | E26: Decimal Number | F26: null
A27: =VLOOKUP(B27,'SITE Fields'!A:A,1,FALSE) -> Latitude (Access) | B27: Latitude (Access) | C27: custrecord_twc_site_latitude_access | D27: RECORD | E27: Decimal Number | F27: null
A28: =VLOOKUP(B28,'SITE Fields'!A:A,1,FALSE) -> Directions | B28: Directions | C28: custrecord_twc_site_directions | D28: RECORD | E28: Long Text | F28: null
A29: =VLOOKUP(B29,'SITE Fields'!A:A,1,FALSE) -> Instructions | B29: Instructions | C29: custrecord_twc_site_instructions | D29: RECORD | E29: Long Text | F29: null
A30: =VLOOKUP(B30,'SITE Fields'!A:A,1,FALSE) -> Tenant Card Required | B30: Tenant Card Required | C30: custrecord_twc_site_tenant_card_req | D30: RECORD | E30: Check Box | F30: null
A31: =VLOOKUP(B31,'SITE Fields'!A:A,1,FALSE) -> 4x4 Required | B31: 4x4 Required | C31: custrecord_twc_site_4x4_req | D31: RECORD | E31: Check Box | F31: null
A32: =VLOOKUP(B32,'SITE Fields'!A:A,1,FALSE) -> Parking Restrictions | B32: Parking Restrictions | C32: custrecord_twc_site_parking_restr | D32: RECORD | E32: Free-Form Text | F32: null
A33: =VLOOKUP(B33,'SITE Fields'!A:A,1,FALSE) -> Crane/Mewp Access | B33: Crane/Mewp Access | C33: custrecord_twc_site_crane_mewp_access | D33: RECORD | E33: Check Box | F33: null
A34: =VLOOKUP(B34,'SITE Fields'!A:A,1,FALSE) -> Safety / Special Notes | B34: Safety / Special Notes | C34: custrecord_twc_site_safety_spl_notes | D34: RECORD | E34: Long Text | F34: null
A35: =VLOOKUP(B35,'SITE Fields'!A:A,1,FALSE) -> Full Demised Area Fenced | B35: Full Demised Area Fenced | C35: custrecord_twc_site_full_dmed_area_fncd | D35: RECORD | E35: Check Box | F35: null
... A37: =VLOOKUP(B37,'SITE Fields'!A:A,1,FALSE) -> Adjacent Ground Owner | B37: Adjacent Ground Owner | C37: custrecord_twc_site_adj_grnd_owner | D37: RECORD | E37: Free-Form Text | F37: null
A38: =VLOOKUP(B38,'SITE Fields'!A:A,1,FALSE) -> Perimeter Type | B38: Perimeter Type | C38: custrecord_twc_site_perimeter_type | D38: RECORD | E38: List/Record | F38: 717
A39: =VLOOKUP(B39,'SITE Fields'!A:A,1,FALSE) -> Fence Height (m) | B39: Fence Height (m) | C39: custrecord_twc_site_fence_height_m | D39: RECORD | E39: Integer Number | F39: null
A40: =VLOOKUP(B40,'SITE Fields'!A:A,1,FALSE) -> Independent Power Supplies | B40: Independent Power Supplies | C40: custrecord_twc_site_indep_pwr_supp | D40: RECORD | E40: Integer Number | F40: null
A41: =VLOOKUP(B41,'SITE Fields'!A:A,1,FALSE) -> Next Generator Service | B41: Next Generator Service | C41: custrecord_twc_site_nxt_gen_svc | D41: RECORD | E41: Date | F41: null
...

Sheet INFRASTRUCTURE Fields
A1: STRUCTURE Field Name | B1: NS Fields ID | C1: NS Field Type | D1: NS Action | F1: DATA SOURCE | G1: AREA | H1: SUB-AREA | I1: Field Type | J1: Option Values | K1: Query/Comment | L1: c heck sample data | M1: Infrastructure Type Relevant
A2: Site | B2: =VLOOKUP(A2,'INFRASTRUCTURE Fields NS'!B:F,1,FALSE) -> Site | C2: =VLOOKUP(A2,'INFRASTRUCTURE Fields NS'!B:F,3,FALSE) -> List/Record | F2: - | G2: Infrastructure | H2: General | I2: SITE Lookup | J2: - | K2: Select SITE Table Entry | L2: 1 | M2: ALL
A3: Infrastructure Type | B3: =VLOOKUP(A3,'INFRASTRUCTURE Fields NS'!B:F,1,FALSE) -> Infrastructure Type | C3: =VLOOKUP(A3,'INFRASTRUCTURE Fields NS'!B:F,3,FALSE) -> List/Record | G3: Infrastructure | H3: General | I3: Option | J3: Structure, Accommodation, Fibre, Generator | K3: NEW FIELD | L3: 2 | M3: ALL
A4: Infrastructure ID | B4: =VLOOKUP(A4,'INFRASTRUCTURE Fields NS'!B:F,1,FALSE) -> Infrastructure ID | C4: =VLOOKUP(A4,'INFRASTRUCTURE Fields NS'!B:F,3,FALSE) -> Free-Form Text | F4: Master Tracker | G4: Infrastructure | H4: General | I4: Free-Form Text | J4: - | K4: Needs to be unique | L4: 3 | M4: ALL
A5: Legacy ID | B5: =VLOOKUP(A5,'INFRASTRUCTURE Fields NS'!B:F,1,FALSE) -> Legacy ID | C5: =VLOOKUP(A5,'INFRASTRUCTURE Fields NS'!B:F,3,FALSE) -> Free-Form Text | F5: Master Tracker | G5: Infrastructure | H5: General | I5: Free-Form Text | J5: - | L5: 4 | M5: Structure
A6: Status | B6: =VLOOKUP(A6,'INFRASTRUCTURE Fields NS'!B:F,1,FALSE) -> Status | C6: =VLOOKUP(A6,'INFRASTRUCTURE Fields NS'!B:F,3,FALSE) -> List/Record | F6: Master Tracker | G6: Infrastructure | H6: General | I6: Option | J6: Live Site, UTS WIP, Option, To be Retired, Retired, Not Live, Planned | L6: 6 | M6: ALL
A7: SRF Status | B7: =VLOOKUP(A7,'INFRASTRUCTURE Fields NS'!B:F,1,FALSE) -> SRF Status | C7: =VLOOKUP(A7,'INFRASTRUCTURE Fields NS'!B:F,3,FALSE) -> List/Record | E7: This should not apply to single site but to the SRF record | F7: Master Tracker | G7: Infrastructure | H7: General | I7: Option | J7: Full SRF, Remove Only, No SRF | L7: 11 | M7: Structure, Accommodation, Fibre
A8: SAF Status | B8: =VLOOKUP(A8,'INFRASTRUCTURE Fields NS'!B:F,1,FALSE) -> SAF Status | C8: =VLOOKUP(A8,'INFRASTRUCTURE Fields NS'!B:F,3,FALSE) -> List/Record | E8: This should not apply to single site but to the SAF record | F8: Master Tracker | G8: Infrastructure | H8: General | I8: Option | J8: Full SAF, Survey only, Op Maintenance only, Construction only, TL only, No SAF | L8: 12 | M8: Structure, Accommodation, Fibre
A9: SAF Auto Approve | B9: =VLOOKUP(A9,'INFRASTRUCTURE Fields NS'!B:F,1,FALSE) -> SAF Auto Approve | C9: =VLOOKUP(A9,'INFRASTRUCTURE Fields NS'!B:F,3,FALSE) -> Check Box | F9: RADIX | G9: Infrastructure | H9: General | I9: Option | J9: No, Yes | K9: This needs to be set to No automatically if the Fall Arrest Certification is Expired | L9: 20 | M9: Structure, Accommodation, Fibre
A10: Schedule | B10: =VLOOKUP(A10,'INFRASTRUCTURE Fields NS'!B:F,1,FALSE) -> Schedule | C10: =VLOOKUP(A10,'INFRASTRUCTURE Fields NS'!B:F,3,FALSE) -> List/Record | F10: Master Tracker | G10: Infrastructure | H10: General | I10: Option | J10: Schedule 1, Schedule 2, Schedule 3a, Schedule 3b, Schedule 3f, MLA, Non MLA site, Option A (EED), TALA, Freehold, Leasehold, LTRU, Option A (3a), Option A (3b), Expansion Space, Schedule 3a: RT | L10: 5 | M10: Structure
A11: Infrastructure Ownership | B11: =VLOOKUP(A11,'INFRASTRUCTURE Fields NS'!B:F,1,FALSE) -> Infrastructure Ownership | C11: =VLOOKUP(A11,'INFRASTRUCTURE Fields NS'!B:F,3,FALSE) -> List/Record | F11: Master Tracker | G11: Infrastructure | H11: General | I11: COMPANY Lookup | J11: - | K11: Select COMPANY Table Entry | L11: 7 | M11: ALL
A12: O&M Ownership | B12: =VLOOKUP(A12,'INFRASTRUCTURE Fields NS'!B:F,1,FALSE) -> O&M Ownership | C12: =VLOOKUP(A12,'INFRASTRUCTURE Fields NS'!B:F,3,FALSE) -> List/Record | F12: Master Tracker | G12: Infrastructure | H12: General | I12: COMPANY Lookup | J12: - | K12: Select COMPANY Table Entry | L12: 8 | M12: ALL
A13: Insurance Ownership | B13: =VLOOKUP(A13,'INFRASTRUCTURE Fields NS'!B:F,1,FALSE) -> Insurance Ownership | C13: =VLOOKUP(A13,'INFRASTRUCTURE Fields NS'!B:F,3,FALSE) -> List/Record | F13: Master Tracker | G13: Infrastructure | H13: General | I13: COMPANY Lookup | J13: - | K13: Select COMPANY Table Entry | L13: 9 | M13: ALL
A14: Marketing Status | B14: =VLOOKUP(A14,'INFRASTRUCTURE Fields NS'!B:F,1,FALSE) -> Marketing Status | C14: =VLOOKUP(A14,'INFRASTRUCTURE Fields NS'!B:F,3,FALSE) -> Check Box | F14: Master Tracker | G14: Infrastructure | H14: General | I14: Option | J14: Yes, No | L14: 10 | M14: ALL
A15: Public | B15: =VLOOKUP(A15,'INFRASTRUCTURE Fields NS'!B:F,1,FALSE) -> Public | C15: =VLOOKUP(A15,'INFRASTRUCTURE Fields NS'!B:F,3,FALSE) -> List/Record | F15: RADIX | G15: Infrastructure | H15: General | I15: Option | J15: Yes All, Tenant Customer only, TL only, No All. | L15: 13 | M15: ALL
A16: Locks List | B16: =VLOOKUP(A16,'INFRASTRUCTURE Fields NS'!B:F,1,FALSE) -> #N/A | C16: =VLOOKUP(A16,'INFRASTRUCTURE Fields NS'!B:F,3,FALSE) -> #N/A | D16: REMOVE / IGNORE (this is a one-to-many) | F16: IN RADIX AND NEW SYSTEM | G16: Infrastructure | H16: Access | I16: List of associated LOCK records | J16: - | K16: List LOCK Table entries with Site field and Infrastructure field matching | L16: OK | M16: Structure, Accommodation, Generator
A17: Planning Records List | B17: =VLOOKUP(A17,'INFRASTRUCTURE Fields NS'!B:F,1,FALSE) -> #N/A | C17: =VLOOKUP(A17,'INFRASTRUCTURE Fields NS'!B:F,3,FALSE) -> #N/A | D17: REMOVE / IGNORE (this is a one-to-many) | G17: Infrastructure | H17: Planning | I17: List of associated PLANNING records | K17: List PLANNING Table entries with Site field and Infrastructure field matching | L17: OK | M17: Structure, Accommodation
A18: Comments | B18: =VLOOKUP(A18,'INFRASTRUCTURE Fields NS'!B:F,1,FALSE) -> Comments | C18: =VLOOKUP(A18,'INFRASTRUCTURE Fields NS'!B:F,3,FALSE) -> Free-Form Text | F18: - | G18: Infrastructure | H18: General | I18: Free-Form Text | J18: - | L18: 14 | M18: ALL
A19: Easting | B19: =VLOOKUP(A19,'INFRASTRUCTURE Fields NS'!B:F,1,FALSE) -> Easting | C19: =VLOOKUP(A19,'INFRASTRUCTURE Fields NS'!B:F,3,FALSE) -> Decimal Number | F19: IN RADIX AND NEW SYSTEM | G19: Infrastructure | H19: Location | I19: 6-digit Decimal (0 decimal points) | J19: - | K19: It would be great to calculate one from the other | L19: 24 | M19: Structure, Accommodation
A20: Northing | B20: =VLOOKUP(A20,'INFRASTRUCTURE Fields NS'!B:F,1,FALSE) -> Northing | C20: =VLOOKUP(A20,'INFRASTRUCTURE Fields NS'!B:F,3,FALSE) -> Decimal Number | F20: IN RADIX AND NEW SYSTEM | G20: Infrastructure | H20: Location | I20: 6-digit Decimal (0 decimal points) | J20: - | L20: 25 | M20: Structure, Accommodation
A21: Longitude | B21: =VLOOKUP(A21,'INFRASTRUCTURE Fields NS'!B:F,1,FALSE) -> Longitude | C21: =VLOOKUP(A21,'INFRASTRUCTURE Fields NS'!B:F,3,FALSE) -> Decimal Number | F21: IN RADIX AND NEW SYSTEM | G21: Infrastructure | H21: Location | I21: Decimal (6 decimal points) | J21: - | L21: 26 | M21: Structure, Accommodation
A22: Latitude | B22: =VLOOKUP(A22,'INFRASTRUCTURE Fields NS'!B:F,1,FALSE) -> Latitude | C22: =VLOOKUP(A22,'INFRASTRUCTURE Fields NS'!B:F,3,FALSE) -> Decimal Number | F22: IN RADIX AND NEW SYSTEM | G22: Infrastructure | H22: Location | I22: Decimal (6 decimal points) | J22: - | L22: 27 | M22: Structure, Accommodation
A23: Structure Type | B23: =VLOOKUP(A23,'INFRASTRUCTURE Fields NS'!B:F,1,FALSE) -> Structure Type | C23: =VLOOKUP(A23,'INFRASTRUCTURE Fields NS'!B:F,3,FALSE) -> List/Record | F23: TLM Tracker | G23: Structure | H23: General | I23: Option | J23: Lattice Mast, Stayed Mast, Monopole, Wooden Pole, Rooftop Mast, Rooftop, No Structure | L23: 15 | M23: Structure
A24: Tower Family | B24: =VLOOKUP(A24,'INFRASTRUCTURE Fields NS'!B:F,1,FALSE) -> Tower Family | C24: =VLOOKUP(A24,'INFRASTRUCTURE Fields NS'!B:F,3,FALSE) -> Free-Form Text | F24: TLM Tracker | G24: Structure | H24: General | I24: Option | J24: See separate tab | K24: - | L24: 16 | M24: Structure
A25: Structure Height (m) | B25: =VLOOKUP(A25,'INFRASTRUCTURE Fields NS'!B:F,1,FALSE) -> Structure Height (m) | C25: =VLOOKUP(A25,'INFRASTRUCTURE Fields NS'!B:F,3,FALSE) -> Decimal Number | F25: TLM Tracker | G25: Structure | H25: General | I25: Decimal (2 decimal points) | J25: - | K25: - | L25: 17 | M25: Structure
A26: Future Planned Structure Height (m) | B26: =VLOOKUP(A26,'INFRASTRUCTURE Fields NS'!B:F,1,FALSE) -> Future Planned Structure Height (m) | C26: =VLOOKUP(A26,'INFRASTRUCTURE Fields NS'!B:F,3,FALSE) -> Decimal Number | F26: n/a | G26: Structure | H26: General | I26: Decimal (2 decimal points) | L26: 18 | M26: Structure
A27: Rooftop Height (m) | B27: =VLOOKUP(A27,'INFRASTRUCTURE Fields NS'!B:F,1,FALSE) -> Rooftop Height (m) | C27: =VLOOKUP(A27,'INFRASTRUCTURE Fields NS'!B:F,3,FALSE) -> Decimal Number | F27: TLM Tracker | G27: Structure | H27: General | I27: Decimal (2 decimal points) | J27: - | K27: - | L27: 19 | M27: Structure
A28: Aircraft Lights List | B28: =VLOOKUP(A28,'INFRASTRUCTURE Fields NS'!B:F,1,FALSE) -> #N/A | C28: =VLOOKUP(A28,'INFRASTRUCTURE Fields NS'!B:F,3,FALSE) -> #N/A | D28: REMOVE / IGNORE (this is a one-to-many) | F28: TBD | G28: Structure | H28: General | I28: List of associated AWL records | J28: - | K28: List AWL Table entries with Site field and Infrastructure field matching | L28: OK | M28: Structure
A29: Fall Arrest Status | B29: =VLOOKUP(A29,'INFRASTRUCTURE Fields NS'!B:F,1,FALSE) -> Fall Arrest Status | C29: =VLOOKUP(A29,'INFRASTRUCTURE Fields NS'!B:F,3,FALSE) -> List/Record | F29: RADIX | G29: Structure | H29: Access | I29: Option | J29: Not Present, Certified, Certification Expired | K29: - | L29: 21 | M29: Structure
A30: Fall Arrest Type | B30: =VLOOKUP(A30,'INFRASTRUCTURE Fields NS'!B:F,1,FALSE) -> Fall Arrest Type | C30: =VLOOKUP(A30,'INFRASTRUCTURE Fields NS'!B:F,3,FALSE) -> List/Record | F30: RADIX | G30: Structure | H30: Access | I30: Option | J30: Latchway, Metreel | K30: Any railok should be considered no fall arrest | L30: 22 | M30: Structure
A31: Anti Climb | B31: =VLOOKUP(A31,'INFRASTRUCTURE Fields NS'!B:F,1,FALSE) -> Anti Climb | C31: =VLOOKUP(A31,'INFRASTRUCTURE Fields NS'!B:F,3,FALSE) -> Check Box | F31: RADIX | G31: Structure | H31: Access | I31: Option | J31: No, Yes | K31: - | L31: 23 | M31: Structure
A32: Next Site Inspection Date | B32: =VLOOKUP(A32,'INFRASTRUCTURE Fields NS'!B:F,1,FALSE) -> Next Site Inspection Date | C32: =VLOOKUP(A32,'INFRASTRUCTURE Fields NS'!B:F,3,FALSE) -> Date | F32: IN RADIX AND NEW SYSTEM | G32: Structure | H32: Inspections | I32: Date | J32: - | K32: - | L32: 28 | M32: Structure
A33: Next Fall Arrest Certification Date | B33: =VLOOKUP(A33,'INFRASTRUCTURE Fields NS'!B:F,1,FALSE) -> Next Fall Arrest Certification Date | C33: =VLOOKUP(A33,'INFRASTRUCTURE Fields NS'!B:F,3,FALSE) -> Date | G33: Structure | H33: Inspections | I33: Date | K33: If the Fall Arrest Status is Present and this date elapses, the Fall Arrest Status should be set to Expired | L33: 29 | M33: Structure
A34: Tower Last Painted Date | B34: =VLOOKUP(A34,'INFRASTRUCTURE Fields NS'!B:F,1,FALSE) -> Tower Last Painted Date | C34: =VLOOKUP(A34,'INFRASTRUCTURE Fields NS'!B:F,3,FALSE) -> Date | F34: IN RADIX AND NEW SYSTEM | G34: Structure | H34: Inspections | I34: Date | J34: - | K34: - | L34: 30 | M34: Structure
A35: Scheduled Next Painting Date | B35: =VLOOKUP(A35,'INFRASTRUCTURE Fields NS'!B:F,1,FALSE) -> Scheduled Next Painting Date | C35: =VLOOKUP(A35,'INFRASTRUCTURE Fields NS'!B:F,3,FALSE) -> Date | F35: IN RADIX AND NEW SYSTEM | G35: Structure | H35: Inspections | I35: Date | J35: - | K35: - | L35: 31 | M35: Structure
A36: Painting Warranty Expiry Date | B36: =VLOOKUP(A36,'INFRASTRUCTURE Fields NS'!B:F,1,FALSE) -> Painting Warranty Expiry Date | C36: =VLOOKUP(A36,'INFRASTRUCTURE Fields NS'!B:F,3,FALSE) -> Date | F36: IN RADIX AND NEW SYSTEM | G36: Structure | H36: Inspections | I36: Date | J36: - | K36: - | L36: 32 | M36: Structure
A37: Structure Inspections List | B37: =VLOOKUP(A37,'INFRASTRUCTURE Fields NS'!B:F,1,FALSE) -> #N/A | C37: =VLOOKUP(A37,'INFRASTRUCTURE Fields NS'!B:F,3,FALSE) -> #N/A | D37: REMOVE / IGNORE (this is a one-to-many) | F37: IN RADIX AND NEW SYSTEM | G37: Structure | H37: Inspections | I37: List of associated INSPECTION records | J37: - | K37: List INSPECTION Table entries with Site field and Infrastructure field matching | L37: OK | M37: Structure
A38: Structure Design | B38: =VLOOKUP(A38,'INFRASTRUCTURE Fields NS'!B:F,1,FALSE) -> Structure Design | C38: =VLOOKUP(A38,'INFRASTRUCTURE Fields NS'!B:F,3,FALSE) -> Text Area | G38: Structure | H38: Design | I38: Text Area | L38: 33 | M38: Structure
A39: Structure Design Schematic | B39: =VLOOKUP(A39,'INFRASTRUCTURE Fields NS'!B:F,1,FALSE) -> #N/A | C39: =VLOOKUP(A39,'INFRASTRUCTURE Fields NS'!B:F,3,FALSE) -> #N/A | D39: create field | G39: Structure | H39: Design | I39: Lookup to files | K39: DEFER FOR A NOW | L39: OK | M39: Structure
A40: Year of Build | B40: =VLOOKUP(A40,'INFRASTRUCTURE Fields NS'!B:F,1,FALSE) -> Year of Build | C40: =VLOOKUP(A40,'INFRASTRUCTURE Fields NS'!B:F,3,FALSE) -> Integer Number | G40: Structure | H40: Design | I40: Integer | L40: 34 | M40: Structure
...

Sheet INFRASTRUCTURE Fields NS
B1: field_label | C1: field_id | D1: field_type | E1: field_foreign_table | F1: include_name
A2: =VLOOKUP(B2,'INFRASTRUCTURE Fields'!A:A,1,FALSE) -> Site | B2: Site | C2: custrecord_twc_infra_ | D2: List/Record | E2: customrecord_twc_site | F2: F
A3: =VLOOKUP(B3,'INFRASTRUCTURE Fields'!A:A,1,FALSE) -> Infrastructure Type | B3: Infrastructure Type | C3: custrecord_twc_infra_types | D3: List/Record | E3: customrecord_twc_infra_types | F3: F
A4: =VLOOKUP(B4,'INFRASTRUCTURE Fields'!A:A,1,FALSE) -> Infrastructure ID | B4: Infrastructure ID | C4: custrecord_twc_infra_id | D4: Free-Form Text | E4: null | F4: F
A5: =VLOOKUP(B5,'INFRASTRUCTURE Fields'!A:A,1,FALSE) -> Legacy ID | B5: Legacy ID | C5: custrecord_twc_infra_legacy_id | D5: Free-Form Text | E5: null | F5: F
A6: =VLOOKUP(B6,'INFRASTRUCTURE Fields'!A:A,1,FALSE) -> Status | B6: Status | C6: custrecord_twc_infra_status | D6: List/Record | E6: customrecord_twc_infra_sts | F6: F
A7: =VLOOKUP(B7,'INFRASTRUCTURE Fields'!A:A,1,FALSE) -> SRF Status | B7: SRF Status | C7: custrecord_twc_infra_srf_status | D7: List/Record | E7: customrecord_twc_infra_srf_sts | F7: F
A8: =VLOOKUP(B8,'INFRASTRUCTURE Fields'!A:A,1,FALSE) -> SAF Status | B8: SAF Status | C8: custrecord_twc_infra_saf_status | D8: List/Record | E8: customrecord_twc_infra_saf_sts | F8: F
A9: =VLOOKUP(B9,'INFRASTRUCTURE Fields'!A:A,1,FALSE) -> SAF Auto Approve | B9: SAF Auto Approve | C9: custrecord_twc_infra_saf_auto_apprv | D9: Check Box | E9: null | F9: F
A10: =VLOOKUP(B10,'INFRASTRUCTURE Fields'!A:A,1,FALSE) -> Schedule | B10: Schedule | C10: custrecord_twc_infra_sch | D10: List/Record | E10: customrecord_twc_infra_sch | F10: F
A11: =VLOOKUP(B11,'INFRASTRUCTURE Fields'!A:A,1,FALSE) -> Infrastructure Ownership | B11: Infrastructure Ownership | C11: custrecord_twc_infra_ownshp | D11: List/Record | E11: -2 | F11: F
A12: =VLOOKUP(B12,'INFRASTRUCTURE Fields'!A:A,1,FALSE) -> O&M Ownership | B12: O&M Ownership | C12: custrecord_twc_infra_om_ownshp | D12: List/Record | E12: -2 | F12: F
A13: =VLOOKUP(B13,'INFRASTRUCTURE Fields'!A:A,1,FALSE) -> Insurance Ownership | B13: Insurance Ownership | C13: custrecord_twc_infra_insur_ownshp | D13: List/Record | E13: -2 | F13: F
A14: =VLOOKUP(B14,'INFRASTRUCTURE Fields'!A:A,1,FALSE) -> Marketing Status | B14: Marketing Status | C14: custrecord_twc_infra_mktg_sts | D14: Check Box | E14: null | F14: F
A15: =VLOOKUP(B15,'INFRASTRUCTURE Fields'!A:A,1,FALSE) -> Public | B15: Public | C15: custrecord_twc_infra_public | D15: List/Record | E15: customrecord_twc_infra_publ | F15: F
A16: =VLOOKUP(B16,'INFRASTRUCTURE Fields'!A:A,1,FALSE) -> #N/A | B16: Locks | C16: custrecord_twc_infra_locks | D16: List/Record | E16: customrecord_twc_lock | F16: F
A17: =VLOOKUP(B17,'INFRASTRUCTURE Fields'!A:A,1,FALSE) -> #N/A | B17: Planning Records | C17: custrecord_twc_infra_pln_rec | D17: List/Record | E17: customrecord_twc_plan | F17: F
A18: =VLOOKUP(B18,'INFRASTRUCTURE Fields'!A:A,1,FALSE) -> Comments | B18: Comments | C18: custrecord_twc_infra_com | D18: Free-Form Text | E18: null | F18: F
A19: =VLOOKUP(B19,'INFRASTRUCTURE Fields'!A:A,1,FALSE) -> Easting | B19: Easting | C19: custrecord_twc_infra_easting | D19: Decimal Number | E19: null | F19: F
A20: =VLOOKUP(B20,'INFRASTRUCTURE Fields'!A:A,1,FALSE) -> Northing | B20: Northing | C20: custrecord_twc_infra_northing | D20: Decimal Number | E20: null | F20: F
A21: =VLOOKUP(B21,'INFRASTRUCTURE Fields'!A:A,1,FALSE) -> Longitude | B21: Longitude | C21: custrecord_twc_infra_lng | D21: Decimal Number | E21: null | F21: F
A22: =VLOOKUP(B22,'INFRASTRUCTURE Fields'!A:A,1,FALSE) -> Latitude | B22: Latitude | C22: custrecord_twc_infra_lat | D22: Decimal Number | E22: null | F22: F
A23: =VLOOKUP(B23,'INFRASTRUCTURE Fields'!A:A,1,FALSE) -> Structure Type | B23: Structure Type | C23: custrecord_twc_infra_str_type | D23: List/Record | E23: customrecord_twc_infra_str_types | F23: F
A24: =VLOOKUP(B24,'INFRASTRUCTURE Fields'!A:A,1,FALSE) -> Tower Family | B24: Tower Family | C24: custrecord_twc_infra_tw_fam | D24: Free-Form Text | E24: null | F24: F
A25: =VLOOKUP(B25,'INFRASTRUCTURE Fields'!A:A,1,FALSE) -> Structure Height (m) | B25: Structure Height (m) | C25: custrecord_twc_infra_str_ht_m | D25: Decimal Number | E25: null | F25: F
... A46: =VLOOKUP(B46,'INFRASTRUCTURE Fields'!A:A,1,FALSE) -> Foundation Dimensions | B46: Foundation Dimensions | C46: custrecord_twc_infra_fnd_dims | D46: Free-Form Text | E46: null | F46: F
A47: =VLOOKUP(B47,'INFRASTRUCTURE Fields'!A:A,1,FALSE) -> Foundation Contractor | B47: Foundation Contractor | C47: custrecord_twc_infra_fnd_contr | D47: List/Record | E47: -2 | F47: F
A48: =VLOOKUP(B48,'INFRASTRUCTURE Fields'!A:A,1,FALSE) -> Soil Bearing DCP/SI (kN/m) | B48: Soil Bearing DCP/SI (kN/m) | C48: custrecord_twc_infra_soil_brg_dcp_si | D48: Decimal Number | E48: null | F48: F
A49: =VLOOKUP(B49,'INFRASTRUCTURE Fields'!A:A,1,FALSE) -> Ground Water (BGL) | B49: Ground Water (BGL) | C49: custrecord_twc_infra_grnd_wtr | D49: Decimal Number | E49: null | F49: F
A50: =VLOOKUP(B50,'INFRASTRUCTURE Fields'!A:A,1,FALSE) -> Foundation FOS | B50: Foundation FOS | C50: custrecord_twc_infra_fnd_fos | D50: Decimal Number | E50: null | F50: F
A51: =VLOOKUP(B51,'INFRASTRUCTURE Fields'!A:A,1,FALSE) -> Foundation Overturning (kN/m) | B51: Foundation Overturning (kN/m) | C51: custrecord_twc_infra_fnd_ot | D51: Decimal Number | E51: null | F51: F
A52: =VLOOKUP(B52,'INFRASTRUCTURE Fields'!A:A,1,FALSE) -> Structure Capacity Σ ESA_(m²) | B52: Structure Capacity Σ ESA_(m²) | C52: custrecord_twc_infra_str_cap_esa | D52: Decimal Number | E52: null | F52: F
A53: =VLOOKUP(B53,'INFRASTRUCTURE Fields'!A:A,1,FALSE) -> Structure Capacity Σ E-BM_(m².m) | B53: Structure Capacity Σ E-BM_(m².m) | C53: custrecord_twc_infra_str_cap_ebm | D53: Decimal Number | E53: null | F53: F
A54: =VLOOKUP(B54,'INFRASTRUCTURE Fields'!A:A,1,FALSE) -> Structure Equipment loading Σ E-BM_(m².m) | B54: Structure Equipment loading Σ E-BM_(m².m) | C54: custrecord_twc_infra_str_equip_ldg_ebm | D54: Decimal Number | E54: null | F54: F
A55: =VLOOKUP(B55,'INFRASTRUCTURE Fields'!A:A,1,FALSE) -> % Capacity used | B55: % Capacity used | C55: custrecord_twc_infra_pct_cap_used | D55: Integer Number | E55: null | F55: F
A56: =VLOOKUP(B56,'INFRASTRUCTURE Fields'!A:A,1,FALSE) -> % Capacity remaining | B56: % Capacity remaining | C56: custrecord_twc_infra_pct_cap_rem | D56: Integer Number | E56: null | F56: F
A57: =VLOOKUP(B57,'INFRASTRUCTURE Fields'!A:A,1,FALSE) -> TLM | B57: TLM | C57: custrecord_twc_infra_tlm | D57: List/Record | E57: customrecord_twc_infra_tlm | F57: F
A58: =VLOOKUP(B58,'INFRASTRUCTURE Fields'!A:A,1,FALSE) -> #N/A | B58: Capacity Reviews | C58: custrecord_twc_infra_cap_rev | D58: List/Record | E58: customrecord_twc_capacity_review | F58: F
A59: =VLOOKUP(B59,'INFRASTRUCTURE Fields'!A:A,1,FALSE) -> Accomodation Type | B59: Accomodation Type | C59: custrecord_twc_infra_accom_type | D59: List/Record | E59: customrecord_twc_infra_accom | F59: F
... A80: =VLOOKUP(B80,'INFRASTRUCTURE Fields'!A:A,1,FALSE) -> Next Generator Service Type | B80: Next Generator Service Type | C80: custrecord_twc_infra_nxt_gen_svc_type | D80: List/Record | E80: customrecord_twc_infra_nxt_gen_svc_type | F80: F

Sheet LOCK Fields
A1: LOCKS Field Name | B1: NS Fields ID | C1: NS Field Type | D1: NS Action | E1: DATA SOURCE | F1: AREA | G1: SUB-AREA | H1: Field Type | I1: Option Values | J1: Query/Comment
A2: Site | E2: - | F2: Locks | G2: - | H2: SITE Lookup | I2: - | J2: Select SITE Table Entry
A3: Lock ID | F3: Locks | H3: Free-Form Text | I3: LOCK-XXXXX
A4: Lock Location Category | F4: Locks | H4: Option | I4: Gate, Gate with Dual Lock, Anti-Climb, Accomodation, Generator, Other
A5: Secured Infrastructure | E5: - | F5: Locks | G5: - | H5: INFRASTRUCTURE Lookup | J5: Select INFRASTRUCTURE Table Entry
A6: Comment | F6: Locks | H6: Free-Form Text
A7: Lock Type | F7: Locks | H7: Option | I7: Locken, Locken Passive, Abloy, Other
A8: Lock Config | D8: create field & Lock Config Table | H8: Option | I8: Euro Cylinder, Long Padlock, Short Padlock, Key Safe | J8: NEW FIELD
A9: Locken Lock Name | D9: create field | H9: Free-Form Text | J9: NEW FIELD
A10: Locken Access Point Reference | F10: Locks | H10: Free-Form Text
A11: Other Reference | D11: create field | F11: Locks | H11: Free-Form Text
A12: A1 Short | F12: Locks | H12: Free-Form Text | J12: REMOVE FIELD
A13: A1 Long | F13: Locks | H13: Free-Form Text | J13: REMOVE FIELD
A14: B1 Short | F14: Locks | H14: Free-Form Text | J14: REMOVE FIELD
A15: B1 Long | F15: Locks | H15: Free-Form Text | J15: REMOVE FIELD
A16: Abloy Cylinders | F16: Locks | H16: Free-Form Text | J16: REMOVE FIELD
A17: Differ Number | F17: Locks | H17: Free-Form Text | J17: REMOVE FIELD
A18: Abloy Lubrication Date | F18: Locks | H18: Date | J18: REMOVE FIELD

Sheet LOCK Fields NS
A1: field_label | B1: field_id | C1: field_type | D1: field_foreign_table | E1: include_name
A2: Site | B2: custrecord_twc_lock_site | C2: List/Record | D2: customrecord_twc_site | E2: F
A3: Lock ID | B3: custrecord_twc_lock_id | C3: Free-Form Text | D3: null | E3: F
A4: Lock Location Category | B4: custrecord_twc_lock_loc_cat | C4: List/Record | D4: customrecord_twc_lock_loc_cat | E4: F
A5: Structure | B5: custrecord_twc_lock_structure | C5: List/Record | D5: customrecord_twc_str_ | E5: F
A6: Accommodation | B6: custrecord_twc_lock_accom | C6: List/Record | D6: customrecord_twc_ac | E6: F
A7: Generator | B7: custrecord_twc_lock_generator | C7: List/Record | D7: customrecord_twc_gen | E7: F
A8: Comment | B8: custrecord_twc_lock_comment | C8: Free-Form Text | D8: null | E8: F
A9: Lock Type | B9: custrecord_twc_lock_type | C9: List/Record | D9: customrecord_twc_lock_type | E9: F
A10: Locken Access Point Reference | B10: custrecord_twc_lock_access_point_ref | C10: Free-Form Text | D10: null | E10: F
A11: Abloy Reference | B11: custrecord_twc_lock_abloy_ref | C11: Free-Form Text | D11: null | E11: F
A12: A1 Short | B12: custrecord_twc_lock_a1_short | C12: Free-Form Text | D12: null | E12: F
... A18: Abloy Lubrication Date | B18: custrecord_twc_lock_abloy_lub_date | C18: Date | D18: null | E18: F
