Workbook

Sheet SITES TEST DATA
A1: Site ID | B1: RADIX Site Table entry number | C1: Site ID | D1: Site Name | E1: Alias | F1: Site Status | G1: Site Type | H1: Multi Mast Sites | I1: Old ID | J1: Height ASL (m) | K1: Site Level | L1: Portfolio | M1: SRF Status | N1: SAF Status | O1: BTS Status | P1: SAF Auto Approve | Q1: Public | R1: Address | S1: Eircode | T1: What3Words | U1: County | V1: Easting | W1: Northing | X1: Longitude | Y1: Latitude | Z1: Track Type | AA1: Easting (Access) | AB1: Northing (Access) | AC1: Latitude (Access) | AD1: Longitude (Access) | AE1: Directions | AF1: Instructions | AG1: Tenant Card Required | AH1: 4x4 Required | AI1: Parking Restrictions | AJ1: Crane/Mewp Access | AK1: Independent Power Supplies | AL1: Safety / Special Notes | AM1: Full Demised Area Fenced | AN1: Adjacent Groud Space | AO1: Adjacent Ground Owner | AP1: Perimeter Type | AQ1: Fence Height (m)
A2: TCK5002 | B2: 2 | C2: TCK5002 | D2: Aherla | F2: Retired | H2: NO | J2: 79 | K2: Level 1 | L2: EED | M2: Full SRF | N2: Full SAF | P2: 1 | Q2: 1 | R2: Aherla | S2: A96AP20 | T2: lsjncpsdjnc | U2: Cork | V2: 150500 | W2: 67057 | X2: 51.85409 | Y2: -8.71912 | Z2: Tarmac | AA2: 150479 | AB2: 67072 | AC2: 51.85422 | AD2: -8.71943 | AE2: From Cork City take N22 towards Macroom. After 14.5km take left turn towards Aherla. Stay on road for 2.3km, after road bears to the right and entering Aherla, take sharp 160 degree left turn. Follow road for 250m and site will be on right hand side. | AF2: 1 x eircom padlock on pedestrian gate and ISEO LOCKEN lock on anticlimb | AG2: 0 | AH2: 0 | AJ2: 1 | AM2: 0 | AN2: 1 | AO2: House on either side of site and field located behind site | AP2: Stone/Chain Link Combination | AQ2: 1.2
A3: TKY6028 | B3: 3 | C3: TKY6028 | D3: Anablaha | E3: Toormore | F3: Active | H3: NO | J3: 181 | K3: Level 2 | L3: TC68 | M3: Full SRF | N3: Full SAF | P3: 1 | Q3: 1 | R3: Toormore, Anablaha | T3: lsjncpsdjnc | U3: Kerry | V3: 102505 | W3: 96387 | X3: 52.11128 | Y3: -9.42384 | Z3: Tarmac | AA3: 102498 | AB3: 96404 | AC3: 52.11143 | AD3: -9.42395 | AE3: From Killarney take N22 towards Castleisland / Ferranfore. After 5.3km on N22, approach crossroads, take right turn heading for Finnegan's Cross. Stay on road for 6.5km, site will be on the right hand side. | AF3: Electronic LOCKEN key required for access | AG3: 0 | AH3: 0 | AJ3: 1 | AM3: 0 | AN3: 1 | AO3: Farmer | AP3: Pallisade | AQ3: 2.4
A4: TGY5003 | B4: 4 | C4: TGY5003 | D4: Ardrahan | E4: Ardrahan exchange ADNL | F4: Active | H4: NO | J4: 39 | K4: Level 2 | L4: EED | M4: Full SRF | N4: Full SAF | P4: 1 | Q4: 1 | R4: Behind Post Office, N18, Ardrahan | T4: lsjncpsdjnc | U4: Galway | V4: 146050 | W4: 212030 | X4: 53.15632 | Y4: -8.80721 | Z4: Tarmac | AA4: 146121 | AB4: 212093 | AC4: 53.15689 | AD4: -8.80616 | AE4: From Galway take N18 towards Gort. After 16.5km arrive in town of Ardrahan. Take right turn immediately after Joyces Pub" followed by immediate left turn towards Garda station and Post office. Take road located between Garda and Post office and follow for 100m, site will be on the left hand side. | AF4: elocks installed | AG4: 0 | AH4: 0 | AJ4: 1 | AM4: 0 | AN4: 1 | AO4: Eircom compound | AP4: Stone/Chain Link Combination | AQ4: 1.2
A5: TWW3001 | B5: 5 | C5: TWW3001 | D5: Arklow | F5: Active | H5: NO | J5: 3 | K5: Level 2 | L5: 108 | M5: Full SRF | N5: Full SAF | P5: 1 | Q5: 1 | R5: Main Street, Arklow Town | T5: lsjncpsdjnc | U5: Wicklow | V5: 324473 | W5: 173563 | X5: 52.799062 | Y5: -6.155261 | AA5: 324445 | AB5: 173524 | AC5: 52.79872 | AD5: -6.15569 | AE5: From N11 take turn for Arklow. Continue into town centre crossing over bridge. Arrive at T-junction, take right turn. Continue straight for approx 300m. Take immediate right after Post Office. Compound gate is located 30m down on the right hand side. Once in compound, take immediate left and continue straight for 40m. Mast is located straight ahead. | AF5: ISEO Locken key required for anticlimb | AG5: 1 | AH5: 0 | AJ5: 1 | AM5: 0 | AN5: 1 | AO5: Eircom | AP5: None
A6: TWW5005 | B6: 6 | C6: TWW5005 | D6: Arklow Town Centre | E6: Arklow Exchange | F6: Active | H6: NO | J6: 24 | K6: Level 2 | L6: EED | M6: Full SRF | N6: Full SAF | P6: 1 | Q6: 1 | R6: Main St, Arklow Town | T6: lsjncpsdjnc | U6: Wicklow | V6: 324456 | W6: 173522 | X6: 52.7987 | Y6: -6.15554 | Z6: Tarmac | AA6: 324445 | AB6: 173524 | AC6: 52.79872 | AD6: -6.15569 | AE6: From N11 take turn off for Arklow Town. In town cross over bridge and continue on road until a T-junction is reached. Take right turn at junction and folow for 300m and take another right turn after Post Office. | AF6: Ensup | AG6: 1 | AH6: 0 | AJ6: 1 | AM6: 0 | AN6: 1 | AO6: eircom / public carpark | AQ6: 1.2
A7: TWW5004 | B7: 7 | C7: TWW5004 | D7: Arklow Town South | E7: Arklow AEH | F7: Active | H7: NO | J7: 55 | K7: Level 4 | L7: EED | M7: Full SRF | N7: Full SAF | P7: 0 | Q7: 1 | R7: Emoclew Rd, Arklow Town | T7: lsjncpsdjnc | U7: Wicklow | V7: 323288 | W7: 172548 | X7: 52.79022 | Y7: -6.17321 | Z7: Tarmac | AA7: 323317 | AB7: 172635 | AC7: 52.79099 | AD7: -6.17274 | AE7: From Dublin take N11 to Arklow Town. After crossing bridge into town follow Main Street around to the right. Continue on Main Street and take left at roundabout onto Wexford Road (R772). Follow for 800m, go straight through roundabout and take right turn immediately after Emoclew Road. Follow for 500m. Site is located on left hand side. | AF7: Eircom main gate and locken iseo compound and locken iseo anticlimb. Go through main compound gate and take 1st left followed by a right turn. Site is located 50m down on L.H.S. ISEO electronic key required for access. | AG7: 0 | AH7: 0 | AJ7: 1 | AM7: 0 | AN7: 1 | AO7: Eircom compound | AP7: Pallisade | AQ7: 2.4
A8: TDL2001 | B8: 8 | C8: TDL2001 | D8: Arranmore | F8: Active | H8: NO | J8: 11 | K8: Level 1 | L8: 108 | M8: Full SRF | N8: Full SAF | P8: 0 | Q8: 1 | R8: Arranmore Island | T8: lsjncpsdjnc | U8: Donegal | V8: 168195 | W8: 415600 | X8: 54.986888 | Y8: -8.49757 | AA8: 168220 | AB8: 415610 | AC8: 54.98698 | AD8: -8.497181 | AE8: Take local ferry from Donegal to Arranmore Island. From the pier follow the road keeping the coast on your left hand side. Access site through gate from the main road. | AF8: Ferry required to Aran Island. | AG8: 0 | AH8: 0 | AJ8: 1 | AM8: 1 | AN8: 1 | AO8: Eircom | AP8: Post & Rail Fence | AQ8: 1.2
A9: TCN5006 | B9: 9 | C9: TCN5006 | D9: Arvanagh | E9: Arvagh TE Exchange(ARVA) | F9: Retired | H9: NO | J9: 75 | K9: Level 1 | L9: EED | M9: Full SRF | N9: Full SAF | P9: 0 | Q9: 1 | R9: Arvangh | T9: lsjncpsdjnc | U9: Cavan | V9: 227855 | W9: 296831 | X9: 53.92021 | Y9: -7.57679 | Z9: Tarmac | AA9: 227836 | AB9: 296796 | AC9: 53.9199 | AD9: -7.57709 | AE9: Travelling from Granard take N55 for 3.5km. Turn left and continue 4.5km, then turn right toward Swan Lake Drive and in 6.4km continue straight for 6.7km. Take sharp right at Main Street (R198) and after 130m site is located on right hand side. | AG9: 0 | AH9: 0 | AJ9: 0 | AM9: 0 | AN9: 1 | AO9: Health board | AP9: Pallisade | AQ9: 2.4
A10: TMH6457 | B10: 10 | C10: TMH6457 | D10: Athboy | F10: UTS | H10: NO | I10: TMH6057 | J10: 65 | K10: Level 3 | L10: TC68 | M10: Full SRF | N10: Full SAF | P10: 0 | Q10: 1 | R10: Athboy | T10: lsjncpsdjnc | U10: Meath | V10: 271766 | W10: 264326 | X10: 53.62401 | Y10: -6.91612 | Z10: Tarmac | AA10: 271796 | AB10: 264289 | AC10: 53.62368 | AD10: -6.91567 | AE10: Travelling on the Navan Road N51, arrive into Athboy and site is located on Lower Bridge Street. Site entrance is located beside garda station. | AF10: Garda gate entrance,Code required for keypad. soon to be automatic gates. | AG10: 0 | AH10: 0 | AJ10: 1 | AM10: 0 | AN10: 1 | AO10: Car wash place
A11: TGY5008 | B11: 12 | C11: TGY5008 | D11: Athenry | F11: Retired | H11: NO | J11: 16 | K11: Level 4 | L11: EED | M11: Full SRF | N11: Full SAF | P11: 0 | Q11: 1 | R11: Cross Street, Athenry | T11: lsjncpsdjnc | U11: Galway | V11: 150227 | W11: 227784 | X11: 53.29826 | Y11: -8.74724 | Z11: Tarmac | AA11: 150242 | AB11: 227767 | AC11: 53.29811 | AD11: -8.74701 | AE11: Travelling to Athenry on the Dublin Road (R347), take second left onto Bridge Street. Site is located on right hand side. | AF11: automatic gate with key code required for main small gate. elocks also installed | AG11: 1 | AH11: 0 | AJ11: 1 | AM11: 0 | AN11: 0 | AO11: Business area | AP11: Pallisade | AQ11: 2.4
A12: TWH4001 | B12: 13 | C12: TWH4001 | D12: Athlone HPO | F12: Active | H12: NO | J12: 42 | K12: Level 3 | L12: 108 | M12: Full SRF | N12: Full SAF | P12: 0 | Q12: 1 | R12: Custume Barracks, Grace Road, Athlone Town | T12: lsjncpsdjnc | U12: Westmeath | V12: 203705 | W12: 241477 | X12: 53.423629 | Y12: -7.945005 | AA12: 203728 | AB12: 241633 | AC12: 53.425025 | AD12: -7.944653 | AE12: Arrive in Athlone town, and take bridge across the Shannon into the west side of Athlone town. As you cross the bridge you will arrive at a roundabout, take last exit onto Grace Road. Follow for 200m and site entrance will be on the left hand side. To access ground equipment same as before cross over bridge but this time take 1st exit at roundabout onto Castle St. Follow one way system for 350m keeping to the right at all times, then take right turn onto Pearse St. Continue on road for 210m and site entrance will be on the left hand side directly after Garda Station. | AF12: 5-7 days notice required for Army Barracks approval prior to access. LOCKEN key required for access to anticlimb. | AG12: 0 | AH12: 0 | AJ12: 1 | AM12: 0 | AN12: 1 | AO12: Eircom | AP12: None
A13: TLK5009 | B13: 14 | C13: TLK5009 | D13: Athlunkard | F13: Active | H13: NO | J13: 16 | K13: Level 3 | L13: EED | M13: Full SRF | N13: Full SAF | P13: 1 | Q13: 1 | R13: Athlunkard | T13: lsjncpsdjnc | U13: Limerick | V13: 159171 | W13: 159411 | X13: 52.6847 | Y13: -8.60446 | Z13: Tarmac | AA13: 159197 | AB13: 159359 | AC13: 52.68423 | AD13: -8.60408 | AE13: Travelling into Limerick on N18 at Coonagh roundabout take 2nd exit onto Ennis Road. After 1km turn left at Dr McCann's Road (N7). At next roundabout take 4th exit to the Island/N7 heading for N24, turn left at Athlinkard Street. At Corbally roundabout take 1st exit, and turn right at Thornbrook. Site is located on right hand side. | AF13: Ensup main gate and elock on internal compound and anticlimb | AG13: 0 | AH13: 0 | AJ13: 1 | AM13: 0 | AN13: 0 | AP13: Pallisade | AQ13: 2.8
A14: TGY6318 | B14: 15 | C14: TGY6318 | D14: Aughrim | E14: Aughrim Exchange | F14: Active | H14: NO | I14: TGY6018 | J14: 63 | K14: Level 2 | L14: TC68 | M14: Full SRF | N14: Full SAF | P14: 0 | Q14: 1 | R14: Aughrim | T14: lsjncpsdjnc | U14: Galway | V14: 178899 | W14: 228106 | X14: 53.30307 | Y14: -8.31724 | Z14: Tarmac | AA14: 178899 | AB14: 228111 | AC14: 53.30312 | AD14: -8.31724 | AE14: Travelling on N6 take first exit and continue onto R338. After 5.3km take right turn in Aughrim. Site is located 260m on right hand side. | AG14: 0 | AH14: 0 | AJ14: 0 | AM14: 0 | AN14: 1 | AO14: western health board
A15: TGY5010 | B15: 16 | C15: TGY5010 | D15: Aughrim | E15: Aughrim Exchange | F15: UTS | H15: NO | J15: 62 | K15: Level 2 | L15: EED | M15: Full SRF | N15: Full SAF | P15: 0 | Q15: 1 | R15: Aughrim | T15: lsjncpsdjnc | U15: Galway | V15: 178899 | W15: 228099 | X15: 53.30301 | Y15: -8.31725 | Z15: Tarmac | AA15: 178899 | AB15: 228111 | AC15: 53.30312 | AD15: -8.31724 | AE15: Travelling on N6 take first exit and continue onto R338. After 5.3km take right turn in Aughrim. Site is located 260m on right hand side. | AG15: 0 | AH15: 0 | AJ15: 0 | AM15: 0 | AN15: 1 | AO15: western health board
A16: TMO6047 | B16: 17 | C16: TMO6047 | D16: Ayle | F16: Active | H16: NO | J16: 51 | K16: Level 2 | L16: TC68 | M16: Full SRF | N16: Full SAF | P16: 1 | Q16: 1 | R16: Ayle | T16: lsjncpsdjnc | U16: Mayo | V16: 107088 | W16: 281651 | X16: 53.77629 | Y16: -9.41005 | Z16: Tarmac | AA16: 107089 | AB16: 281632 | AC16: 53.77612 | AD16: -9.41003 | AE16: Travelling from Westport take R330 for Ballinrobe for 7.4km. Site is located on the left hand side, opposite the pub. | AF16: electronic key required to access site | AG16: 0 | AH16: 0 | AJ16: 0 | AM16: 0 | AN16: 1 | AO16: eircom | AP16: Pallisade | AQ16: 2.8
A17: TDU7001 | B17: 18 | C17: TDU7001 | D17: Balbriggan | F17: UTS | H17: NO | I17: TDU5011 | J17: 19 | K17: Level 4 | L17: EED | M17: Full SRF | N17: Full SAF | P17: 1 | Q17: 1 | R17: Oakleigh St, Balbriggan | T17: lsjncpsdjnc | U17: Dublin | V17: 319949 | W17: 263990 | X17: 53.61219 | Y17: -6.18836 | Z17: Tarmac | AA17: 319942 | AB17: 264003 | AC17: 53.612308 | AD17: -6.188452 | AE17: From Dublin take M1 to Balbriggan, take exit onto R132 into Balbriggan town. In town take left onto Main St, follow for 250m (passing school on left hand side) and take left turn onto Oakleigh Street. Site is located a further 25m on the left hand side. | AF17: Eircom gates and padlock | AG17: 0 | AH17: 0 | AJ17: 1 | AM17: 0 | AN17: 1 | AO17: Housing estate and eircom compound | AP17: Pallisade | AQ17: 2.4
A18: TMO5012 | B18: 20 | C18: TMO5012 | D18: Balla | F18: Retired | H18: NO | J18: 46 | K18: Level 1 | L18: EED | M18: Full SRF | N18: Full SAF | P18: 0 | Q18: 1 | R18: Balla | T18: lsjncpsdjnc | U18: Mayo | V18: 125654 | W18: 284185 | X18: 53.80204 | Y18: -9.12912 | Z18: Tarmac | AA18: 125589 | AB18: 284180 | AC18: 53.80198 | AD18: -9.1301 | AE18: Travelling from Claremorris take the N60 for 13km, when arriving into Ball take left turn. Site located 250m on left behind playground. | AF18: ISEO LOCKEN key required for access | AG18: 0 | AH18: 0 | AI18: Yes | AJ18: 0 | AM18: 0 | AN18: 1 | AO18: Garda/eircom area behind site,large field
A19: TRN7002 | B19: 22 | C19: TRN7002 | D19: Ballaghadereen | F19: Active | H19: NO | I19: TRN5014 | J19: 81 | K19: Level 2 | L19: EED | M19: Full SRF | N19: Full SAF | P19: 1 | Q19: 1 | R19: Circular Rd, Ballaghadereen | T19: lsjncpsdjnc | U19: Roscommon | V19: 162085 | W19: 294690 | X19: 53.90034 | Y19: -8.57753 | Z19: Tarmac | AA19: 162096 | AB19: 294661 | AC19: 53.90008 | AD19: -8.57736 | AE19: From Frenchpark take N5 to Ballaghadereen. Arrive in Ballaghadereen and take right turn after Towey's Petrol Station onto Circular Road. Follow road for 125m and site will be on the right hand side. | AF19: Eircom gate with padlock on daisy chain. VF lock on anti climb | AG19: 0 | AH19: 0 | AJ19: 1 | AM19: 0 | AN19: 1 | AO19: Eircom compound | AP19: Pallisade/Chain Link Combination | AQ19: 2.4
A20: TMO1001 | B20: 23 | C20: TMO1001 | D20: Ballina | F20: Active | H20: NO | J20: 18 | K20: Premium | L20: 108 | M20: Full SRF | N20: Full SAF | P20: 1 | Q20: 1 | R20: Ballina | T20: lsjncpsdjnc | U20: Mayo | V20: 123826 | W20: 318432 | X20: 54.109386 | Y20: -9.165398 | AA20: 123883 | AB20: 318275 | AC20: 54.107981 | AD20: -9.164494 | AE20: In Ballina Town, take N26 (towards Foxford). Follow for 0.5km and take right turn (just before train station). Stayed 100m tower is visible on the right hand side. Follow track across field to compound. | AF20: Track across grass field. Muddy in winter, use 4x4. ISEO Locken ekey required for access. | AG20: 0 | AH20: 1 | AI20: No | AJ20: 1 | AL20: Caution advised when driving to site, to stay wires/blocks to be avoided. | AM20: 1 | AN20: 1 | AO20: Towercom | AP20: Pallisade | AQ20: 2.8
A21: TWX5030 | B21: 24 | C21: TWX5030 | D21: Ballinaboola | E21: Ballynabola RSU | F21: Retired | H21: NO | J21: 68 | K21: Level 1 | L21: EED | M21: Full SRF | N21: Full SAF | P21: 1 | Q21: 1 | R21: Ballinaboola | T21: lsjncpsdjnc | U21: Wexford | V21: 279380 | W21: 124670 | X21: 52.368302 | Y21: -6.835331 | Z21: Tarmac | AA21: 279358 | AB21: 124641 | AC21: 52.36805 | AD21: -6.83566 | AE21: From Dublin take N11 to Wexford. In Wexford take turn off for N25 at roundabout heading for New Ross. Continue on road for 22.5km and arrive in Ballinaboola. On entering the town the site will be on left hand side, beside turn off onto R737 heading for Wellington Bridge. | AF21: elock installed | AG21: 0 | AH21: 0 | AJ21: 1 | AM21: 0 | AN21: 1 | AO21: Farmers land | AP21: Pallisade | AQ21: 2.4
A22: TCK6005 | B22: 25 | C22: TCK6005 | D22: Ballinaclashet | F22: Active | H22: NO | J22: 45 | K22: Level 2 | L22: TC68 | M22: Full SRF | N22: Full SAF | P22: 1 | Q22: 1 | R22: Ballinaclashet, Oatlands Cross Roads (R611), Bellgooley | T22: lsjncpsdjnc | U22: Cork | V22: 169290 | W22: 53776 | X22: 51.73608 | Y22: -8.44525 | Z22: Tarmac | AA22: 169302 | AB22: 53751 | AC22: 51.73586 | AD22: -8.44508 | AE22: From Cork take N27 towards airport. At roundabout take R600 towards Belgooley. In Bellgooley take left turn after Campus Petrol Station / Huntsman Bar onto the R611. Follow road for 2.8km. Site will be on the left hand side. | AF22: ISEO LOCKEN Electronic key required for access. | AG22: 0 | AH22: 0 | AJ22: 1 | AM22: 0 | AN22: 1 | AO22: Eircom / farmer | AP22: Timber Fence | AQ22: 1.8
A23: TGY5016 | B23: 26 | C23: TGY5016 | D23: Ballinasloe | F23: Active | H23: NO | J23: 60 | K23: Level 2 | L23: EED | M23: Full SRF | N23: Full SAF | P23: 0 | Q23: 1 | R23: Eircom exchange, St. Michaels Square, Ballinasloe | T23: lsjncpsdjnc | U23: Galway | V23: 185304 | W23: 230974 | X23: 53.32906 | Y23: -8.22131 | Z23: Tarmac | AA23: 185339 | AB23: 230998 | AC23: 53.32928 | AD23: -8.22078 | AE23: From Dublin take N4/N6 towards Galway. On N6 take first Ballinasloe exit. Follow signs into town. After crossing bridge follow road for 130m and take right hand turn onto Bridge St. Continue on road for a further 180m and take left turn on Main St, continue on again for 120m and take left turn in St. Michaels Square. Site will be located at end of square on right hand side opposite church. | AF23: 4m Access ladder required | AG23: 0 | AH23: 0 | AJ23: 1 | AM23: 0 | AN23: 1 | AO23: An Post | AQ23: 1.2
A24: TMO2002 | B24: 28 | C24: TMO2002 | D24: Ballinrobe | F24: Active | H24: NO | J24: 33 | K24: Level 3 | L24: 108 | M24: Full SRF | N24: Full SAF | P24: 1 | Q24: 1 | R24: High Street, Ballinrobe | T24: lsjncpsdjnc | U24: Mayo | V24: 118921 | W24: 264516 | X24: 53.624354 | Y24: -9.226138 | AA24: 119022 | AB24: 264534 | AC24: 53.62453 | AD24: -9.22461 | AE24: From Tuam, travel along the R332 onto N84 to Ballinrobe. Keep left through the town and follow road around to right. Turn left for Castlebar (N84). Turn left immediately after bridge to eircom building entrance. Access to compound through main gates, via carpark. | AF24: ISEO LOCKEN Electronic key required for access | AG24: 0 | AH24: 0 | AJ24: 1 | AM24: 1 | AN24: 1 | AO24: Eircom | AP24: Pallisade | AQ24: 3.2
A25: TDL5019 | B25: 29 | C25: TDL5019 | D25: Ballintra | F25: Active | H25: NO | J25: 40 | K25: Level 1 | L25: EED | M25: Full SRF | N25: Full SAF | P25: 1 | Q25: 1 | R25: Ballintra | T25: lsjncpsdjnc | U25: Donegal | V25: 192067 | W25: 369961 | X25: 54.57787 | Y25: -8.12343 | Z25: Tarmac | AA25: 191965 | AB25: 369974 | AC25: 54.577989 | AD25: -8.12499 | AE25: Travelling from Donegal head South on N15. Continue for 11.2km, then turn left at Abbey Park. After 200m take first left onto Main Street and in 85m site is located on right hand side. | AG25: 0 | AH25: 0 | AJ25: 1 | AM25: 0 | AN25: 1 | AO25: Farmer | AP25: Pallisade | AQ25: 3
A26: TDU5020 | B26: 31 | C26: TDU5020 | D26: Ballyboden | F26: Active | H26: NO | J26: 42 | K26: Premium | L26: EED | M26: Full SRF | N26: Full SAF | P26: 1 | Q26: 1 | R26: Scholarstown Rd, Ballyboden | T26: lsjncpsdjnc | U26: Dublin | V26: 313418 | W26: 226918 | X26: 53.2807 | Y26: -6.30034 | Z26: Tarmac | AA26: 313390 | AB26: 226840 | AC26: 53.28001 | AD26: -6.30079 | AE26: From M50 take exit 12. At roundabout take first exit for Ballyboden / Knocklyon. At next roundabout take second exit. Follow road to another roundabout and take last exit onto Scholarstown Road. Follow road for 650m, site entrance will be on left hand side, directly opposite right turn signposted for Rathfarnham Golf Club / DSPCA. | AF26: Electronic key required. 2 x eircom locks on gates. | AG26: 0 | AH26: 0 | AJ26: 1 | AM26: 0 | AN26: 1 | AO26: Houses/gardens surround compound on all sides | AP26: Pallisade/Chain Link Combination | AQ26: 2.4
A27: TKY6029 | B27: 32 | C27: TKY6029 | D27: Ballydavid | F27: Active | H27: NO | J27: 26 | K27: Level 1 | L27: TC68 | M27: Full SRF | N27: Full SAF | P27: 1 | Q27: 1 | R27: Ballydavid | T27: lsjncpsdjnc | U27: Kerry | V27: 38864 | W27: 106875 | X27: 52.19059 | Y27: -10.35707 | Z27: Tarmac | AA27: 38848 | AB27: 106873 | AC27: 52.19057 | AD27: -10.3573 | AE27: Travelling on N86 from Dingle, take first exit on roundabout onto R559. At next roundabout take first exit and stay on R559. After 8.2km take right turn. Site is located on left hand side. | AF27: ISEO LOCKEN ekey required for access | AG27: 0 | AH27: 0 | AJ27: 1 | AM27: 0 | AN27: 0 | AP27: Pallisade | AQ27: 2.8
A28: TGY6419 | B28: 34 | C28: TGY6419 | D28: Ballygar | F28: Active | H28: NO | I28: TGY6019 | J28: 60 | K28: Level 2 | L28: TC68 | M28: Full SRF | N28: Full SAF | P28: 1 | Q28: 1 | R28: Ballygar | T28: lsjncpsdjnc | U28: Galway | V28: 178262 | W28: 252490 | X28: 53.52213 | Y28: -8.32848 | Z28: Tarmac | AA28: 178281 | AB28: 252458 | AC28: 53.52185 | AD28: -8.3282 | AE28: Traveling from Mountbellew on N63 arrive into Ballygar. Site is located behind Garda Station on left hand side. | AF28: Access/right of way through garda station. ISEO Locken ekey required for access. | AG28: 0 | AH28: 0 | AI28: Yes | AJ28: 0 | AM28: 0 | AN28: 1 | AO28: Housing | AP28: Pallisade | AQ28: 2.8
A29: TCK6006 | B29: 35 | C29: TCK6006 | D29: Ballygarvan | F29: Active | H29: NO | J29: 70 | K29: Level 3 | L29: TC68 | M29: Full SRF | N29: Full SAF | P29: 1 | Q29: 1 | R29: Ballygarvan, Bowens Cross, Ballygarvan | T29: lsjncpsdjnc | U29: Cork | V29: 167465 | W29: 63707 | X29: 51.82523 | Y29: -8.4726 | Z29: Tarmac | AA29: 167465 | AB29: 63714 | AC29: 51.82529 | AD29: -8.4726 | AE29: From Dublin take M7/M8 to Cork, arrive in Cork and proceed through Jack Lynch tunnel onto the N25. Continue until turn off for N27 towards airport. Follow N27 for 3km and take turn on R600 (old Kinsale Road). Continue on for approx 9.2km until you reach crossroads with signs for left turn towards The Garden Pavillion" and "Park Liam McCarthy". Take the left turn and follow road for 50m, site will be located on right hand side. | AF29: ISEO LOCKEN ekey required for access. | AG29: 0 | AH29: 0 | AJ29: 1 | AM29: 0 | AN29: 1 | AO29: Farmer | AP29: Pallisade | AQ29: 2.4
A30: TWW1002 | B30: 37 | C30: TWW1002 | D30: Ballyguile - 52m | F30: Active | H30: NO | J30: 166 | K30: Level 3 | L30: 108 | M30: Full SRF | N30: Full SAF | P30: 0 | Q30: 1 | R30: Ballyguile, Wicklow Town | T30: lsjncpsdjnc | U30: Wicklow | V30: 331119 | W30: 192539 | X30: 52.967899 | Y30: -6.049156 | AA30: 331380 | AB30: 193078 | AC30: 52.97268 | AD30: -6.04504 | AE30: Travel into Wicklow Town, continue on Main Street. Take a right turn onto Kilmainham Hill, follow road onto Convent Road and then take left into Ballyguile housing estate. Take the first right and the gate to site will be on the right hand side after 25m. | AF30: elocks installed on site | AG30: 0 | AH30: 1 | AI30: No | AJ30: 1 | AL30: Anti-social behaviour has been reported in the area of this site. Lone working not recommended. | AM30: 1 | AN30: 1 | AO30: Co.co | AP30: Pallisade | AQ30: 3
A31: TMO6048 | B31: 39 | C31: TMO6048 | D31: Ballyhaunis | F31: Active | H31: NO | J31: 88 | K31: Level 2 | L31: TC68 | M31: Full SRF | N31: Full SAF | P31: 1 | Q31: 1 | R31: Ballyhaunis | T31: lsjncpsdjnc | U31: Mayo | V31: 149388 | W31: 279749 | X31: 53.76503 | Y31: -8.76822 | Z31: Tarmac | AA31: 149398 | AB31: 279751 | AC31: 53.76505 | AD31: -8.76806 | AE31: Travelling from Knock take R323 toward Airport Road for 10.3km. Arrive in Ballyhaunis and continue up to Main Street. Take left turn onto Beach Park and continue straight to St. Gerard's Cresent. Site is located on left hand side. | AG31: 0 | AH31: 0 | AJ31: 1 | AM31: 0 | AN31: 1 | AO31: Housing | AP31: Pallisade | AQ31: 2.8
A32: TMO7003 | B32: 40 | C32: TMO7003 | D32: Ballyhaunis | F32: Active | H32: NO | I32: TMO5023 | J32: 88 | K32: Level 2 | L32: EED | M32: Full SRF | N32: Full SAF | P32: 1 | Q32: 1 | R32: Ballyhaunis | T32: lsjncpsdjnc | U32: Mayo | V32: 149388 | W32: 279749 | X32: 53.76503 | Y32: -8.76822 | Z32: Tarmac | AA32: 149398 | AB32: 279751 | AC32: 53.76505 | AD32: -8.76806 | AE32: Travelling from Knock take R323 toward Airport Road for 10.3km. Arrive in Ballyhaunis and continue up to Main Street. Take left turn onto Beach Park and continue straight to St. Gerard's Cresent. Site is located on left hand side. | AF32: Elock on internal compound and anticlimb | AG32: 0 | AH32: 0 | AJ32: 1 | AM32: 0 | AN32: 1 | AO32: Housing | AP32: Pallisade | AQ32: 2.8
A33: TMO5024 | B33: 41 | C33: TMO5024 | D33: Ballyhean | E33: Ballyhean RSU | F33: Active | H33: NO | J33: 41 | K33: Level 1 | L33: EED | M33: Full SRF | N33: Full SAF | P33: 0 | Q33: 1 | R33: Attavally | T33: lsjncpsdjnc | U33: Mayo | V33: 114001 | W33: 280810 | X33: 53.76993 | Y33: -9.30499 | Z33: Tarmac | AA33: 113977 | AB33: 280819 | AC33: 53.77 | AD33: -9.30536 | AE33: From Ballinrobe take N84 towards Castlebar. Follow for 17km and take sharp right turn signposted for Attavally". Follow road for 75m and site will be on the left hand side." | AG33: 0 | AH33: 0 | AJ33: 1 | AM33: 0 | AN33: 1 | AO33: Farmers field on 3 sides | AP33: Stone/Chain Link Combination | AQ33: 1.2
A34: TKY7004 | B34: 42 | C34: TKY7004 | D34: Ballyheige | F34: Active | H34: NO | I34: TKY5025 | J34: 19 | K34: Level 1 | L34: EED | M34: Full SRF | N34: Full SAF | P34: 0 | Q34: 1 | R34: Ballyheige | T34: lsjncpsdjnc | U34: Kerry | V34: 75724 | W34: 128312 | X34: 52.39267 | Y34: -9.8263 | Z34: Tarmac | AA34: 75707 | AB34: 128314 | AC34: 52.39268 | AD34: -9.82655 | AE34: Travelling from Tralee on the R551 head Northwest. Continue straight and site is located 140m on the right hand side. | AG34: 0 | AH34: 0 | AJ34: 0 | AM34: 0 | AN34: 0
A35: TLK1003 | B35: 43 | C35: TLK1003 | D35: Ballyhoura | F35: Active | H35: NO | J35: 436 | K35: Level 3 | L35: 108 | M35: Full SRF | N35: Full SAF | P35: 0 | Q35: 1 | R35: Ballyhoura Mountain | T35: lsjncpsdjnc | U35: Limerick | V35: 161633 | W35: 117265 | X35: 52.306162 | Y35: -8.563212 | AA35: 163089 | AB35: 112378 | AC35: 52.262344 | AD35: -8.541331 | AE35: From Mitchelstown, take N73 towards Mallow. 3km after Kildorrery, take right turn for Donerail. Take the third right, then first right. This road leads all the way to the mast and is approx 9km long. | AF35: ISEO Locken ekey required for access. | AG35: 0 | AH35: 1 | AJ35: 1 | AM35: 1 | AN35: 1 | AO35: Towercom | AP35: Pallisade | AQ35: 3.2
A36: TCK4002 | B36: 45 | C36: TCK4002 | D36: Ballymakeeraa | F36: Active | H36: NO | J36: 122 | K36: Level 1 | L36: 108 | M36: Full SRF | N36: Full SAF | P36: 0 | Q36: 1 | R36: Cul Na Carrig Rd, Ballymakeera | T36: lsjncpsdjnc | U36: Cork | V36: 121356 | W36: 76663 | X36: 51.937058 | Y36: -9.144212 | AA36: 121360 | AB36: 76638 | AC36: 51.936832 | AD36: -9.144144 | AE36: Travelling from Ballycasheen travel South on the N22 for 14km to the village of Ballymakeeraa. Site entrance located after the centra shop on the left hand side. Entrance located 200m on left hand side. | AG36: 0 | AH36: 0 | AJ36: 1 | AM36: 0 | AN36: 1 | AO36: Eircom | AP36: None
A37: TRN5028 | B37: 46 | C37: TRN5028 | D37: Ballymoe | E37: Ballymoe Exchange | F37: Retired | H37: NO | J37: 59 | K37: Level 1 | L37: EED | M37: Full SRF | N37: Full SAF | P37: 0 | Q37: 1 | R37: Ballymoe | T37: lsjncpsdjnc | U37: Roscommon | V37: 170229 | W37: 272160 | X37: 53.69846 | Y37: -8.45147 | Z37: Tarmac | AA37: 170238 | AB37: 272146 | AC37: 53.69834 | AD37: -8.45133 | AE37: Travelling from Roscommon head North on Castle Street (N61) toward Cherry Drive. After 600m at roundabout take first exit onto racecourse (N60). Continue for 18.7km and site located on the right hand side. | AF37: ISEO electronic key required for site access. | AG37: 0 | AH37: 0 | AJ37: 0 | AM37: 0 | AN37: 1 | AO37: farmer | AP37: Timber Fence | AQ37: 2.4
A38: TWH6065 | B38: 47 | C38: TWH6065 | D38: Ballymore | F38: Active | H38: NO | J38: 81 | K38: Level 2 | L38: TC68 | M38: Full SRF | N38: Full SAF | P38: 1 | Q38: 1 | R38: Ballymore | T38: lsjncpsdjnc | U38: Westmeath | V38: 221854 | W38: 249079 | X38: 53.49148 | Y38: -7.67149 | Z38: Tarmac | AA38: 221861 | AB38: 249063 | AC38: 53.49134 | AD38: -7.67139 | AE38: Travelling from Mullingar heading West on R390, after 19.4km turn left onto Lower Street (R390) and site is located on right hand side. | AF38: ISEO Locken key required for access. | AG38: 0 | AH38: 0 | AJ38: 0 | AM38: 0 | AN38: 1 | AO38: Eircom | AP38: Pallisade | AQ38: 2.8
A39: TKE5029 | B39: 48 | C39: TKE5029 | D39: Ballymore Eustace | E39: Ballymore Eustace TE | F39: Retired | H39: NO | J39: 137 | K39: Level 2 | L39: EED | M39: Full SRF | N39: Full SAF | P39: 0 | Q39: 1 | R39: Ballymore Eustace | T39: lsjncpsdjnc | U39: Kildare | V39: 292585 | W39: 210300 | X39: 53.13551 | Y39: -6.61732 | Z39: Tarmac | AA39: 292580 | AB39: 210297 | AC39: 53.13545 | AD39: -6.61746 | AE39: From Naas take R411 and continue for 9.1km. Site is located on the right hand side. | AF39: elocks installed | AG39: 0 | AH39: 0 | AJ39: 0 | AM39: 0 | AN39: 1 | AO39: School grounds | AP39: Pallisade | AQ39: 2.4
A40: TSO5027 | B40: 49 | C40: TSO5027 | D40: Ballymote | F40: To be retired | H40: NO | J40: 80 | K40: Level 4 | L40: EED | M40: Full SRF | N40: Full SAF | P40: 0 | Q40: 1 | R40: Ballymote | T40: lsjncpsdjnc | U40: Sligo | V40: 166234 | W40: 315598 | X40: 54.08846 | Y40: -8.51674 | Z40: Tarmac | AA40: 166285 | AB40: 315630 | AC40: 54.08875 | AD40: -8.51596 | AE40: Travelling from Tubbercurry take R294 for 5.8km. Continue onto R296 for 1.8km, then turn left. After 550m turn right on R296 and continue for 4.7km. Take right turn and continue for 3km. Take right turn at Lord Edward Street and after 84m site is located on the right hand side. | AF40: Access through an Post gate, also lock on the gate | AG40: 0 | AH40: 0 | AJ40: 1 | AM40: 0 | AN40: 1 | AO40: AN Post
...

Sheet INFRASTRUCTURE TEST DATA
A2: Site | B2: Infrastructure Type | C2: Infrastructure ID | D2: Legacy ID | E2: Schedule | F2: Status | G2: Infrastructure Ownership | H2: O&M Ownership | I2: Insurance Ownership | J2: Marketing Status | K2: SRF Status | L2: SAF Status | M2: Public | N2: Comments | O2: Structure Type | P2: Tower Family | Q2: Structure Height (m) | R2: Future Planned Structure Height (m) | S2: Rooftop Height (m) | T2: SAF Auto Approve | U2: Fall Arrest Status | V2: Fall Arrest Type | W2: Anti Climb | X2: Easting | Y2: Northing | Z2: Longitude | AA2: Latitude | AB2: Next Site Inspection Date | AC2: Next Fall Arrest Certification Date | AD2: Tower Last Painted Date | AE2: Scheduled Next Painting Date | AF2: Painting Warranty Expiry Date | AG2: Structure Design | AH2: Year of Build | AI2: Geotype | AJ2: Proximity to Body of Water (km) | AK2: Land Topology | AL2: Wind Map Vb,map (m/s) | AM2: Foundation Type | AN2: Foundation Design | AO2: Foundation Dimensions | AP2: Foundation Contractor | AQ2: Soil Bearing DCP/SI (kN/m) | AR2: Ground Water (BGL) | AS2: Foundation FOS | AT2: Foundation Overturning (kN/m) | AU2: Structure Capacity Σ ESA_(m²) | AV2: Structure Capacity Σ E-BM_(m².m) | AW2: Structure Equipment loading Σ E-BM_(m².m) | AX2: % Capacity used | AY2: % Capacity remaining | AZ2: TLM | BA2: Accomodation Type | BB2: Accommodation Dimensions | BC2: Rack Spaces Available | BD2: Units | BE2: Model | BF2: Installed | BG2: AC Feed Phase | BH2: Loadings | BI2: Noise Level | BJ2: Next Aircon Service | BK2: Intruder Alarm Present | BL2: Intruder Code | BM2: Fire Alarm Present | BN2: Next Fire Service | BO2: Next Alarm Service | BP2: Generator Model | BQ2: Power Capacity | BR2: Tank Capacity (l) | BS2: Next Generator Service | BT2: Next Generator Service Type | BU2: Fibre Infrastructure Status | BV2: Fibre Duct Installed | BW2: Fibre Infrastructure Type | BX2: Fibre Service Providers | BY2: Fibre Priority | BZ2: Fibre Phase | CA2: Fibre Partner Priority | CB2: Fibre Comments
A3: TLK5001 | B3: Structure | C3: TLK5001-T01 | E3: MLA | F3: To be Retired | G3: Vodafone | H3: Towercom | I3: Vodafone | J3: 0 | K3: Remove Only | L3: Full SAF | M3: 1 | O3: Lattice Tower | P3: Eve Type 6 | Q3: 12 | T3: 0 | U3: 0 | W3: 0 | X3: 111282 | Y3: 126159 | Z3: 52.38024 | AA3: -9.30358 | AB3: 45585.958 | AG3: DEL-6 A-E | AH3: 1993-1996 | AI3: Country | AJ3: 23 | AK3: Flat | AL3: 26.5 | AM3: Pile | AN3: Concrete Grade: Main Rebar: Corner/Secondary Rebar: Concrete Quantity (m3): Reinforcement Quantity (kg): | AO3: 0 | AP3: Obelisk | AQ3: 0 | AR3: 0 | AS3: 21 | AT3: 0 | AU3: 1.932 | AV3: 200.1 | AW3: 232 | AX3: 0 | AY3: 1 | AZ3: 0
A4: TLK5001 | B4: Structure | C4: TLK5001-T02 | D4: TLK7301 | E4: Option A (EED) | F4: Active | G4: Eircom | H4: Towercom | I4: Eircom | J4: 1 | K4: Full SRF | L4: Full SAF | M4: 1 | O4: Lattice Tower | P4: V6X | Q4: 20 | T4: 0 | U4: 0 | W4: 0 | X4: 111282 | Y4: 126159 | Z4: 52.38024 | AA4: -9.30358 | AB4: 45585.958 | AG4: FL87 | AH4: 2022 | AI4: Country | AJ4: 24 | AK4: Flat | AL4: 26.5 | AM4: Pad | AN4: Concrete Grade: Main Rebar: Corner/Secondary Rebar: Concrete Quantity (m3): Reinforcement Quantity (kg): | AO4: 6.6 x 6.6 x 1.25 | AP4: KTL | AQ4: 0 | AR4: 0 | AS4: 393 | AT4: 0 | AU4: 23.93 | AV4: 10.22 | AW4: 10.22 | AX4: 0.65 | AY4: 0.35 | AZ4: Green
A5: TCK5002 | B5: Structure | C5: TCK5002-T01 | E5: MLA | F5: Retired | G5: Vodafone | H5: Towercom | I5: Vodafone | J5: 0 | K5: No SRF | L5: TL Only | M5: 0 | T5: 0 | U5: 1 | V5: Latchway | W5: 1 | X5: 150500 | Y5: 67057 | Z5: 51.85409 | AA5: -8.71912 | AB5: 46589.958 | AC5: 46224 | AG5: DEL-6 A-E | AH5: #N/A | AI5: #N/A | AJ5: 25 | AK5: #N/A | AL5: #N/A | AM5: Slab | AN5: Concrete Grade: Main Rebar: Corner/Secondary Rebar: Concrete Quantity (m3): Reinforcement Quantity (kg): | AO5: #N/A | AP5: Obelisk | AQ5: #N/A | AR5: #N/A | AS5: 12 | AT5: #N/A | AU5: 100.23 | AV5: 90.5 | AW5: 90.5 | AX5: #N/A | AY5: #N/A | AZ5: #N/A
A6: TCK5002 | B6: Structure | C6: TCK5002-T02 | E6: MLA | F6: Active | G6: Vodafone | H6: Towercom | I6: Vodafone | J6: 1 | K6: Full SRF | L6: Full SAF | M6: 1 | T6: 1 | U6: 1 | V6: Latchway | W6: 1 | X6: 150500 | Y6: 67057 | Z6: 51.85409 | AA6: -8.71912 | AB6: 46589.958 | AC6: 46224 | AG6: FL88 | AH6: #N/A | AI6: #N/A | AJ6: 26 | AK6: #N/A | AL6: #N/A | AM6: Pile | AN6: Concrete Grade: Main Rebar: Corner/Secondary Rebar: Concrete Quantity (m3): Reinforcement Quantity (kg): | AO6: #N/A | AP6: KTL | AQ6: #N/A | AR6: #N/A | AS6: 133 | AT6: #N/A | AU6: 140.32867 | AV6: -9.3266667 | AW6: -9.3266667 | AX6: #N/A | AY6: #N/A | AZ6: #N/A
A7: TKY6028 | B7: Structure | C7: TKY6028-T01 | E7: Schedule 3f | F7: Active | G7: Towercom | H7: Towercom | I7: Towercom | J7: 1 | K7: Full SRF | L7: Full SAF | M7: 1 | O7: Monopole | P7: Type - 25m - 03 | Q7: 25 | T7: 1 | U7: 1 | V7: Metreel | W7: 1 | X7: 102505 | Y7: 96387 | Z7: 52.11128 | AA7: -9.42384 | AB7: 46126.958 | AG7: DEL-6 A-E | AH7: 2008-2010 | AI7: country | AJ7: 27 | AK7: flat | AL7: 26.5 | AM7: Pad | AN7: Concrete Grade: Main Rebar: Corner/Secondary Rebar: Concrete Quantity (m3): Reinforcement Quantity (kg): | AO7: 5.3 x 5.3 x 1.0 | AP7: Obelisk | AQ7: 0 | AR7: 0 | AS7: 128.5 | AT7: 0 | AU7: 189.47767 | AV7: -64.126667 | AW7: 10.917778 | AX7: 0.45 | AY7: 0.55 | AZ7: green
A8: TGY5003 | B8: Structure | C8: TGY5003-T01 | E8: MLA | F8: Active | G8: Vodafone | H8: Towercom | I8: Vodafone | J8: 1 | K8: Full SRF | L8: Full SAF | M8: 1 | O8: Lattice Tower | P8: Eve Type 6 | Q8: 15 | T8: 1 | U8: 0 | W8: 1 | X8: 146050 | Y8: 212030 | Z8: 53.15632 | AA8: -8.80721 | AB8: 46369 | AG8: FL89 | AH8: 1993-1996 | AI8: Country | AJ8: 28 | AK8: Flat | AL8: 26.5 | AM8: Slab | AN8: Concrete Grade: Main Rebar: Corner/Secondary Rebar: Concrete Quantity (m3): Reinforcement Quantity (kg): | AO8: 3.55 x 3.55 | AP8: KTL | AQ8: 0 | AR8: 0 | AS8: 124 | AT8: 549 | AU8: 238.62667 | AV8: -118.92667 | AW8: 1.1444444 | AX8: 0.94998624 | AY8: 0.050013761 | AZ8: Amber
A9: TGY5003 | B9: Structure | C9: TGY5003-T02 | D9: TGY7302 | E9: Option A (EED) | F9: Option | G9: Eircom | H9: Towercom | I9: Eircom | J9: 1 | K9: Full SRF | L9: Full SAF | M9: 1 | P9: No Structure | Q9: 0 | T9: 0 | U9: 0 | W9: 1 | X9: 146050 | Y9: 212030 | Z9: 53.15632 | AA9: -8.80721 | AB9: 46369 | AG9: DEL-6 A-E | AH9: N/A | AI9: Country | AJ9: 29 | AK9: Flat | AL9: 26.5 | AM9: Pile | AN9: Concrete Grade: Main Rebar: Corner/Secondary Rebar: Concrete Quantity (m3): Reinforcement Quantity (kg): | AO9: 0 | AP9: Obelisk | AQ9: 0 | AR9: 0 | AS9: 119.5 | AT9: 0 | AU9: 287.77567 | AV9: -173.72667 | AW9: -8.6288889 | AX9: 0 | AY9: 1 | AZ9: 0
A10: TWW3001 | B10: Structure | C10: TWW3001-T01 | E10: Schedule 3a | F10: Active | G10: Towercom | H10: Towercom | I10: Towercom | J10: 1 | K10: Full SRF | L10: Full SAF | M10: 1 | O10: Lattice Tower | P10: Type - JCM - 4 | Q10: 12 | T10: 1 | U10: 0 | W10: 1 | X10: 324473 | Y10: 173563 | Z10: 52.799062 | AA10: -6.155261 | AB10: 46595.958 | AC10: 46224 | AG10: FL90 | AH10: 0 | AI10: town | AJ10: 30 | AK10: flat | AL10: 25 | AM10: Pad | AN10: Concrete Grade: Main Rebar: Corner/Secondary Rebar: Concrete Quantity (m3): Reinforcement Quantity (kg): | AO10: 0 | AP10: KTL | AQ10: 0 | AR10: 0 | AS10: 115 | AT10: 0 | AU10: 336.92467 | AV10: -228.52667 | AW10: -18.402222 | AX10: 0.86 | AY10: 0.14 | AZ10: Amber
A11: TWW5005 | B11: Structure | C11: TWW5005-R01 | E11: MLA | F11: Active | G11: Vodafone | H11: Towercom | I11: Vodafone | J11: 1 | K11: Full SRF | L11: Full SAF | M11: 1 | O11: Rooftop | P11: Ballast & Pole Mount | Q11: 15.4 | S11: 10 | T11: 1 | U11: 0 | W11: 0 | X11: 324456 | Y11: 173522 | Z11: 52.7987 | AA11: -6.15554 | AB11: 46345 | AG11: DEL-6 A-E | AH11: N/A | AI11: town | AJ11: 31 | AK11: flat | AL11: 25 | AM11: Slab | AN11: Concrete Grade: Main Rebar: Corner/Secondary Rebar: Concrete Quantity (m3): Reinforcement Quantity (kg): | AO11: 0 | AP11: Obelisk | AQ11: 0 | AR11: 0 | AS11: 110.5 | AT11: 0 | AU11: 386.07367 | AV11: -283.32667 | AW11: -28.175556 | AX11: 0.9 | AY11: 0.1 | AZ11: Amber
A12: TWW5004 | B12: Structure | C12: TWW5004-T01 | E12: MLA | F12: Active | G12: Vodafone | H12: Towercom | I12: Vodafone | J12: 1 | K12: Full SRF | L12: Full SAF | M12: 1 | O12: Lattice Tower | P12: Eve Type 5 | Q12: 30 | T12: 0 | U12: 0 | W12: 1 | X12: 323288 | Y12: 172548 | Z12: 52.79022 | AA12: -6.17321 | AB12: 46190.958 | AG12: FL91 | AH12: 1993-1996 | AI12: Town | AJ12: 32 | AK12: flat | AL12: 25 | AM12: Pile | AN12: Concrete Grade: Main Rebar: Corner/Secondary Rebar: Concrete Quantity (m3): Reinforcement Quantity (kg): | AO12: 7.4m x 7.4m | AP12: KTL | AQ12: 0 | AR12: N/A | AS12: 106 | AT12: 0 | AU12: 435.22267 | AV12: -338.12667 | AW12: -37.948889 | AX12: 0.41 | AY12: 0.59 | AZ12: Green
A13: TDL2001 | B13: Structure | C13: TDL2001-T01 | E13: Schedule 2 | F13: Active | G13: Towercom | H13: Towercom | I13: Towercom | J13: 1 | K13: Full SRF | L13: Full SAF | M13: 1 | O13: Guyed Mast | P13: Type - P&T - 4 | Q13: 20 | T13: 0 | U13: 0 | W13: 0 | X13: 168195 | Y13: 415600 | Z13: 54.986888 | AA13: -8.49757 | AB13: 46197.958 | AG13: DEL-6 A-E | AH13: 0 | AI13: country | AJ13: 33 | AK13: hill | AL13: 27 | AM13: Pad | AN13: Concrete Grade: Main Rebar: Corner/Secondary Rebar: Concrete Quantity (m3): Reinforcement Quantity (kg): | AO13: 0 | AP13: Obelisk | AQ13: 0 | AR13: 0 | AS13: 101.5 | AT13: 0 | AU13: 484.37167 | AV13: -392.92667 | AW13: -47.722222 | AX13: 0.85 | AY13: 0.15 | AZ13: Amber
A14: TCN5006 | B14: Structure | C14: TCN5006-T01 | E14: MLA | F14: Retired | G14: Vodafone | H14: Towercom | I14: Vodafone | J14: 0 | K14: No SRF | L14: TL Only | M14: 0 | T14: 0 | U14: 1 | V14: Latchway | W14: 1 | X14: 227855 | Y14: 296831 | Z14: 53.92021 | AA14: -7.57679 | AB14: 46129.958 | AG14: FL92 | AH14: #N/A | AI14: #N/A | AJ14: 34 | AK14: #N/A | AL14: #N/A | AM14: Slab | AN14: Concrete Grade: Main Rebar: Corner/Secondary Rebar: Concrete Quantity (m3): Reinforcement Quantity (kg): | AO14: #N/A | AP14: KTL | AQ14: #N/A | AR14: #N/A | AS14: 97 | AT14: #N/A | AU14: 533.52067 | AV14: -447.72667 | AW14: -57.495556 | AX14: #N/A | AY14: #N/A | AZ14: #N/A
A15: TCN5006 | B15: Structure | C15: TCN5006-T02 | E15: MLA | F15: Active | G15: Vodafone | H15: Towercom | I15: Vodafone | J15: 1 | K15: Full SRF | L15: Full SAF | M15: 1 | O15: Lattice Tower | P15: V6X | Q15: 24 | T15: 0 | U15: 1 | V15: Latchway | W15: 1 | X15: 227855 | Y15: 296831 | Z15: 53.92021 | AA15: -7.57679 | AB15: 46129.958 | AG15: DEL-6 A-E | AH15: 2023 | AI15: Country | AJ15: 35 | AK15: Flat | AL15: 25.5 | AM15: Pile | AN15: Concrete Grade: Main Rebar: Corner/Secondary Rebar: Concrete Quantity (m3): Reinforcement Quantity (kg): | AO15: 6.6 x 6.6 x 1.25 | AP15: Obelisk | AQ15: 0 | AR15: 0 | AS15: 92.5 | AT15: 0 | AU15: 582.66967 | AV15: -502.52667 | AW15: -67.268889 | AX15: 0.65 | AY15: 0.35 | AZ15: Green
A16: TMH6457 | B16: Structure | C16: TMH6457-T01 | D16: TMH6057 | E16: Schedule 3b | F16: UTS | G16: Towercom | H16: Towercom | I16: Towercom | J16: 1 | K16: Full SRF | L16: Full SAF | M16: 1 | T16: 0 | U16: 0 | W16: 0 | X16: 271766 | Y16: 264326 | Z16: 53.62401 | AA16: -6.91612 | AB16: 46540.958 | AG16: FL93 | AH16: #N/A | AI16: #N/A | AJ16: 36 | AK16: #N/A | AL16: #N/A | AM16: Pad | AN16: Concrete Grade: Main Rebar: Corner/Secondary Rebar: Concrete Quantity (m3): Reinforcement Quantity (kg): | AO16: #N/A | AP16: KTL | AQ16: #N/A | AR16: #N/A | AS16: 88 | AT16: #N/A | AU16: 631.81867 | AV16: -557.32667 | AW16: -77.042222 | AX16: #N/A | AY16: #N/A | AZ16: #N/A
A17: TLK5007 | B17: Structure | C17: TLK5007-T01 | E17: MLA | F17: Active | G17: Vodafone | H17: Towercom | I17: Vodafone | J17: 1 | K17: Full SRF | L17: Full SAF | M17: 1 | T17: 0 | U17: 0 | W17: 0 | X17: 112555 | Y17: 134994 | Z17: 52.45982 | AA17: -9.2872 | AB17: 46532.958 | AG17: DEL-6 A-E | AH17: #N/A | AI17: #N/A | AJ17: 37 | AK17: #N/A | AL17: #N/A | AM17: Slab | AN17: Concrete Grade: Main Rebar: Corner/Secondary Rebar: Concrete Quantity (m3): Reinforcement Quantity (kg): | AO17: #N/A | AP17: Obelisk | AQ17: #N/A | AR17: #N/A | AS17: 83.5 | AT17: #N/A | AU17: 680.96767 | AV17: -612.12667 | AW17: -86.815556 | AX17: #N/A | AY17: #N/A | AZ17: #N/A
A18: TLK5007 | B18: Structure | C18: TLK5007-T02 | D18: TLK7303 | E18: Option A (EED) | F18: Option | G18: Eircom | H18: Towercom | I18: Eircom | J18: 1 | K18: Full SRF | L18: Full SAF | M18: 1 | T18: 0 | U18: 0 | W18: 0 | X18: 112555 | Y18: 134994 | Z18: 52.45982 | AA18: -9.2872 | AB18: 46532.958 | AG18: FL94 | AH18: #N/A | AI18: #N/A | AJ18: 38 | AK18: #N/A | AL18: #N/A | AM18: Pile | AN18: Concrete Grade: Main Rebar: Corner/Secondary Rebar: Concrete Quantity (m3): Reinforcement Quantity (kg): | AO18: #N/A | AP18: KTL | AQ18: #N/A | AR18: #N/A | AS18: 79 | AT18: #N/A | AU18: 730.11667 | AV18: -666.92667 | AW18: -96.588889 | AX18: #N/A | AY18: #N/A | AZ18: #N/A
A19: TGY5008 | B19: Structure | C19: TGY5008-T01 | E19: MLA | F19: Retired | G19: Vodafone | H19: Towercom | I19: Vodafone | J19: 0 | K19: No SRF | L19: TL Only | M19: 0 | T19: 0 | U19: 1 | V19: Metreel | W19: 1 | X19: 150227 | Y19: 227784 | Z19: 53.29826 | AA19: -8.74724 | AB19: 46477.958 | AG19: DEL-6 A-E | AH19: #N/A | AI19: #N/A | AJ19: 39 | AK19: #N/A | AL19: #N/A | AM19: Pad | AN19: Concrete Grade: Main Rebar: Corner/Secondary Rebar: Concrete Quantity (m3): Reinforcement Quantity (kg): | AO19: #N/A | AP19: Obelisk | AQ19: #N/A | AR19: #N/A | AS19: 74.5 | AT19: #N/A | AU19: 779.26567 | AV19: -721.72667 | AW19: -106.36222 | AX19: #N/A | AY19: #N/A | AZ19: #N/A
A20: TGY5008 | B20: Structure | C20: TGY5008-T02 | E20: MLA | F20: Active | G20: Vodafone | H20: Towercom | I20: Vodafone | J20: 1 | K20: Full SRF | L20: Full SAF | M20: 1 | T20: 0 | U20: 1 | V20: Metreel | W20: 1 | X20: 150227 | Y20: 227784 | Z20: 53.29826 | AA20: -8.74724 | AB20: 46477.958 | AG20: FL95 | AH20: #N/A | AI20: #N/A | AJ20: 40 | AK20: #N/A | AL20: #N/A | AM20: Slab | AN20: Concrete Grade: Main Rebar: Corner/Secondary Rebar: Concrete Quantity (m3): Reinforcement Quantity (kg): | AO20: #N/A | AP20: KTL | AQ20: #N/A | AR20: #N/A | AS20: 70 | AT20: #N/A | AU20: 828.41467 | AV20: -776.52667 | AW20: -116.13556 | AX20: #N/A | AY20: #N/A | AZ20: #N/A
A21: TWH4001 | B21: Structure | C21: TWH4001-T01 | E21: Schedule 3b | F21: Active | G21: Towercom | H21: Towercom | I21: Towercom | J21: 1 | K21: Full SRF | L21: Full SAF | M21: 1 | O21: Lattice Tower | P21: Type - JCM - 6 | Q21: 37 | T21: 0 | U21: 0 | W21: 0 | X21: 203705 | Y21: 241477 | Z21: 53.423629 | AA21: -7.945005 | AB21: 46038 | AD21: 45505.958 | AF21: 49157.958 | AG21: DEL-6 A-E | AH21: 0 | AI21: town | AJ21: 41 | AK21: flat | AL21: 25.5 | AM21: Pile | AN21: Concrete Grade: Main Rebar: Corner/Secondary Rebar: Concrete Quantity (m3): Reinforcement Quantity (kg): | AO21: Strengthening works 2024 | AP21: Obelisk | AQ21: 0 | AR21: 0 | AS21: 65.5 | AT21: 0 | AU21: 877.56367 | AV21: -831.32667 | AW21: -125.90889 | AX21: 0.85 | AY21: 0.15 | AZ21: Amber
A22: TLK5009 | B22: Structure | C22: TLK5009-T01 | E22: MLA | F22: Active | G22: Vodafone | H22: Towercom | I22: Vodafone | J22: 1 | K22: Full SRF | L22: Full SAF | M22: 1 | O22: Lattice Tower | P22: Eve Type 5 | Q22: 20 | T22: 1 | U22: 1 | V22: Latchway | W22: 1 | X22: 159171 | Y22: 159411 | Z22: 52.6847 | AA22: -8.60446 | AB22: 46651.958 | AG22: FL96 | AH22: 1993-1996 | AI22: Country | AJ22: 42 | AK22: Flat | AL22: 26 | AM22: Pad | AN22: Concrete Grade: Main Rebar: Corner/Secondary Rebar: Concrete Quantity (m3): Reinforcement Quantity (kg): | AO22: 7.1m x 7.1m | AP22: KTL | AQ22: 0 | AR22: Headframe | AS22: 61 | AT22: 0 | AU22: 926.71267 | AV22: -886.12667 | AW22: -135.68222 | AX22: 0.45 | AY22: 0.55 | AZ22: Green
A23: TGY6318 | B23: Structure | C23: TGY6318-T01 | D23: TGY6018 | E23: Schedule 3a | F23: Active | G23: Towercom | H23: Towercom | I23: Towercom | J23: 1 | K23: Full SRF | L23: Full SAF | M23: 1 | T23: 0 | U23: 0 | W23: 0 | X23: 178899 | Y23: 228106 | Z23: 53.30307 | AA23: -8.31724 | AB23: 45791.958 | AG23: DEL-6 A-E | AH23: #N/A | AI23: #N/A | AJ23: 43 | AK23: #N/A | AL23: #N/A | AM23: Slab | AN23: Concrete Grade: Main Rebar: Corner/Secondary Rebar: Concrete Quantity (m3): Reinforcement Quantity (kg): | AO23: #N/A | AP23: Obelisk | AQ23: #N/A | AR23: #N/A | AS23: 56.5 | AT23: #N/A | AU23: 975.86167 | AV23: -940.92667 | AW23: -145.45556 | AX23: #N/A | AY23: #N/A | AZ23: #N/A
A24: TGY5010 | B24: Structure | C24: TGY5010-T01 | E24: MLA | F24: UTS | G24: Vodafone | H24: Towercom | I24: Vodafone | J24: 1 | K24: Full SRF | L24: Full SAF | M24: 1 | O24: Wooden Pole | P24: Wooden Pole | Q24: 12 | T24: 0 | U24: 0 | W24: 0 | X24: 178899 | Y24: 228099 | Z24: 53.30301 | AA24: -8.31725 | AB24: 45820.958 | AG24: FL97 | AH24: 1990-2001 | AI24: Country | AJ24: 44 | AK24: Flat | AL24: 25.5 | AM24: Pile | AN24: Concrete Grade: Main Rebar: Corner/Secondary Rebar: Concrete Quantity (m3): Reinforcement Quantity (kg): | AO24: 0 | AP24: KTL | AQ24: 0 | AR24: 0 | AS24: 52 | AT24: 0 | AU24: 1025.0107 | AV24: -995.72667 | AW24: -155.22889 | AX24: 0.95 | AY24: 0.05 | AZ24: Blue
A25: TMO6047 | B25: Structure | C25: TMO6047-T01 | E25: Schedule 3f | F25: Active | G25: Towercom | H25: Towercom | I25: Towercom | J25: 1 | K25: Full SRF | L25: Full SAF | M25: 1 | O25: Monopole | P25: Del_3 - 15 | Q25: 15 | T25: 1 | U25: 1 | V25: Metreel | W25: 1 | X25: 107088 | Y25: 281651 | Z25: 53.77629 | AA25: -9.41005 | AB25: 46457 | AG25: DEL-6 A-E | AH25: 2008-2010 | AI25: country | AJ25: 45 | AK25: flat | AL25: 26.5 | AM25: Pad | AN25: Concrete Grade: Main Rebar: Corner/Secondary Rebar: Concrete Quantity (m3): Reinforcement Quantity (kg): | AO25: 3.5 x 3.5 x 1.25 | AP25: Obelisk | AQ25: 0 | AR25: 0 | AS25: 47.5 | AT25: 0 | AU25: 1074.1597 | AV25: -1050.5267 | AW25: -165.00222 | AX25: 0.45 | AY25: 0.55 | AZ25: green
A26: TDU7001 | B26: Structure | C26: TDU7001-T01 | D26: TDU5011 | E26: Non MLA | F26: UTS | G26: Vodafone | H26: Towercom | I26: Vodafone | J26: 1 | K26: Full SRF | L26: Full SAF | M26: 1 | T26: 1 | U26: 0 | W26: 1 | X26: 319949 | Y26: 263990 | Z26: 53.61219 | AA26: -6.18836 | AB26: 46247.958 | AG26: FL98 | AH26: #N/A | AI26: #N/A | AJ26: 46 | AK26: #N/A | AL26: #N/A | AM26: Slab | AN26: Concrete Grade: Main Rebar: Corner/Secondary Rebar: Concrete Quantity (m3): Reinforcement Quantity (kg): | AO26: #N/A | AP26: KTL | AQ26: #N/A | AR26: #N/A | AS26: 43 | AT26: #N/A | AU26: 1123.3087 | AV26: -1105.3267 | AW26: -174.77556 | AX26: #N/A | AY26: #N/A | AZ26: #N/A
A27: TMO5012 | B27: Structure | C27: TMO5012-T01 | E27: MLA | F27: Retired | G27: Vodafone | H27: Towercom | I27: Vodafone | J27: 0 | K27: No SRF | L27: TL Only | M27: 0 | T27: 0 | U27: 1 | V27: Metreel | W27: 1 | X27: 125654 | Y27: 284185 | Z27: 53.80204 | AA27: -9.12912 | AB27: 46620.958 | AG27: DEL-6 A-E | AH27: #N/A | AI27: #N/A | AJ27: 47 | AK27: #N/A | AL27: #N/A | AM27: Pile | AN27: Concrete Grade: Main Rebar: Corner/Secondary Rebar: Concrete Quantity (m3): Reinforcement Quantity (kg): | AO27: #N/A | AP27: Obelisk | AQ27: #N/A | AR27: #N/A | AS27: 38.5 | AT27: #N/A | AU27: 1172.4577 | AV27: -1160.1267 | AW27: -184.54889 | AX27: #N/A | AY27: #N/A | AZ27: #N/A
A28: TMO5012 | B28: Structure | C28: TMO5012-T02 | E28: MLA | F28: Active | G28: Vodafone | H28: Towercom | I28: Vodafone | J28: 1 | K28: Full SRF | L28: Full SAF | M28: 1 | T28: 0 | U28: 1 | V28: Metreel | W28: 1 | X28: 125654 | Y28: 284185 | Z28: 53.80204 | AA28: -9.12912 | AB28: 46620.958 | AG28: FL99 | AH28: #N/A | AI28: #N/A | AJ28: 48 | AK28: #N/A | AL28: #N/A | AM28: Pad | AN28: Concrete Grade: Main Rebar: Corner/Secondary Rebar: Concrete Quantity (m3): Reinforcement Quantity (kg): | AO28: #N/A | AP28: KTL | AQ28: #N/A | AR28: #N/A | AS28: 34 | AT28: #N/A | AU28: 1221.6067 | AV28: -1214.9267 | AW28: -194.32222 | AX28: #N/A | AY28: #N/A | AZ28: #N/A
A29: TRN7002 | B29: Structure | C29: TRN7002-T01 | D29: TRN5014 | E29: Non MLA | F29: Active | G29: Vodafone | H29: Towercom | I29: Vodafone | J29: 1 | K29: Full SRF | L29: Full SAF | M29: 1 | T29: 1 | U29: 0 | W29: 1 | X29: 162085 | Y29: 294690 | Z29: 53.90034 | AA29: -8.57753 | AB29: 45938.958 | AG29: DEL-6 A-E | AH29: #N/A | AI29: #N/A | AJ29: 49 | AK29: #N/A | AL29: #N/A | AM29: Slab | AN29: Concrete Grade: Main Rebar: Corner/Secondary Rebar: Concrete Quantity (m3): Reinforcement Quantity (kg): | AO29: #N/A | AP29: Obelisk | AQ29: #N/A | AR29: #N/A | AS29: 29.5 | AT29: #N/A | AU29: 1270.7557 | AV29: -1269.7267 | AW29: -204.09556 | AX29: #N/A | AY29: #N/A | AZ29: #N/A
A30: TMO1001 | B30: Structure | C30: TMO1001-T01 | E30: Schedule 1 | F30: Active | G30: Towercom | H30: Towercom | I30: Towercom | J30: 1 | K30: Full SRF | L30: Full SAF | M30: 1 | O30: Guyed Mast | P30: Type - FLI - 1 | Q30: 106 | T30: 1 | U30: 0 | W30: 0 | X30: 123826 | Y30: 318432 | Z30: 54.109386 | AA30: -9.165398 | AB30: 46422 | AD30: 42850.958 | AF30: 46502.958 | AG30: FL100 | AH30: 0 | AI30: town | AJ30: 50 | AK30: flat | AL30: 26.5 | AM30: Pile | AN30: Concrete Grade: Main Rebar: Corner/Secondary Rebar: Concrete Quantity (m3): Reinforcement Quantity (kg): | AO30: 0 | AP30: KTL | AQ30: 0 | AR30: 0 | AS30: 25 | AT30: 0 | AU30: 1319.9047 | AV30: -1324.5267 | AW30: -213.86889 | AX30: 0.95 | AY30: 0.05 | AZ30: Amber
A31: TWX5030 | B31: Structure | C31: TWX5030-T01 | E31: MLA | F31: Retired | G31: Vodafone | H31: Towercom | I31: Vodafone | J31: 0 | K31: No SRF | L31: TL Only | M31: 0 | T31: 0 | U31: 1 | V31: Latchway | W31: 1 | X31: 279380 | Y31: 124670 | Z31: 52.368302 | AA31: -6.835331 | AB31: 46596.958 | AG31: DEL-6 A-E | AH31: #N/A | AI31: #N/A | AJ31: 51 | AK31: #N/A | AL31: #N/A | AM31: Pad | AN31: Concrete Grade: Main Rebar: Corner/Secondary Rebar: Concrete Quantity (m3): Reinforcement Quantity (kg): | AO31: #N/A | AP31: Obelisk | AQ31: #N/A | AR31: #N/A | AS31: 20.5 | AT31: #N/A | AU31: 1369.0537 | AV31: -1379.3267 | AW31: -223.64222 | AX31: #N/A | AY31: #N/A | AZ31: #N/A
A32: TWX5030 | B32: Structure | C32: TWX5030-T02 | E32: MLA | F32: Active | G32: Vodafone | H32: Towercom | I32: Vodafone | J32: 1 | K32: Full SRF | L32: Full SAF | M32: 1 | T32: 1 | U32: 1 | V32: Latchway | W32: 1 | X32: 279380 | Y32: 124670 | Z32: 52.368302 | AA32: -6.835331 | AB32: 46596.958 | AG32: FL101 | AH32: #N/A | AI32: #N/A | AJ32: 52 | AK32: #N/A | AL32: #N/A | AM32: Slab | AN32: Concrete Grade: Main Rebar: Corner/Secondary Rebar: Concrete Quantity (m3): Reinforcement Quantity (kg): | AO32: #N/A | AP32: KTL | AQ32: #N/A | AR32: #N/A | AS32: 16 | AT32: #N/A | AU32: 1418.2027 | AV32: -1434.1267 | AW32: -233.41556 | AX32: #N/A | AY32: #N/A | AZ32: #N/A
A33: TCK6005 | B33: Structure | C33: TCK6005-T01 | E33: Schedule 3f | F33: Active | G33: Towercom | H33: Towercom | I33: Towercom | J33: 1 | K33: Full SRF | L33: Full SAF | M33: 1 | O33: Monopole | P33: Type - 25m - 03 | Q33: 25 | T33: 1 | U33: 1 | V33: Metreel | W33: 1 | X33: 169290 | Y33: 53776 | Z33: 51.73608 | AA33: -8.44525 | AB33: 46193.958 | AG33: DEL-6 A-E | AH33: 2008-2010 | AI33: country | AJ33: 53 | AK33: flat | AL33: 26 | AM33: Pile | AN33: Concrete Grade: Main Rebar: Corner/Secondary Rebar: Concrete Quantity (m3): Reinforcement Quantity (kg): | AO33: 5.3 x 5.3 x 1.0 | AP33: Obelisk | AQ33: 0 | AR33: 0 | AS33: 11.5 | AT33: 0 | AU33: 1467.3517 | AV33: -1488.9267 | AW33: -243.18889 | AX33: 0.45 | AY33: 0.55 | AZ33: green
A34: TGY5016 | B34: Structure | C34: TGY5016-R01 | E34: MLA | F34: Active | G34: Vodafone | H34: Towercom | I34: Vodafone | J34: 1 | K34: Full SRF | L34: Full SAF | M34: 1 | O34: Rooftop | P34: Pole Mount | Q34: 10 | S34: 10 | T34: 0 | U34: 1 | V34: Metreel | W34: 0 | X34: 185304 | Y34: 230974 | Z34: 53.32906 | AA34: -8.22131 | AB34: 46668.958 | AG34: FL102 | AH34: N/A | AI34: town | AJ34: 54 | AK34: flat | AL34: 25.5 | AM34: Pad | AN34: Concrete Grade: Main Rebar: Corner/Secondary Rebar: Concrete Quantity (m3): Reinforcement Quantity (kg): | AO34: 0 | AP34: KTL | AQ34: 0 | AR34: metreel ladder issue | AS34: 7 | AT34: 0 | AU34: 1516.5007 | AV34: -1543.7267 | AW34: -252.96222 | AX34: 0.9 | AY34: 0.1 | AZ34: Amber
A35: TCK5018 | B35: Structure | C35: TCK5018-T01 | D35: TCK7400 | E35: MLA | F35: To be Retired | G35: Vodafone | H35: Towercom | I35: Vodafone | J35: 0 | K35: Remove Only | L35: Full SAF | M35: 1 | T35: 0 | U35: 0 | W35: 0 | X35: 162189 | Y35: 62061 | Z35: 51.81011 | AA35: -8.54894 | AB35: 45897.958 | AG35: DEL-6 A-E | AH35: #N/A | AI35: #N/A | AJ35: 55 | AK35: #N/A | AL35: #N/A | AM35: Slab | AN35: Concrete Grade: Main Rebar: Corner/Secondary Rebar: Concrete Quantity (m3): Reinforcement Quantity (kg): | AO35: #N/A | AP35: Obelisk | AQ35: #N/A | AR35: #N/A | AS35: 2.5 | AT35: #N/A | AU35: 1565.6497 | AV35: -1598.5267 | AW35: -262.73556 | AX35: #N/A | AY35: #N/A | AZ35: #N/A
A36: TCK5018 | B36: Structure | C36: TCK5018-T02 | D36: TCK7400 | E36: MLA | F36: Active | G36: Vodafone | H36: Towercom | I36: Vodafone | J36: 1 | K36: Full SRF | L36: Full SAF | M36: 1 | T36: 0 | U36: 0 | W36: 0 | X36: 162189 | Y36: 62061 | Z36: 51.81011 | AA36: -8.54894 | AB36: 45897.958 | AG36: FL103 | AH36: #N/A | AI36: #N/A | AJ36: 56 | AK36: #N/A | AL36: #N/A | AM36: Pile | AN36: Concrete Grade: Main Rebar: Corner/Secondary Rebar: Concrete Quantity (m3): Reinforcement Quantity (kg): | AO36: #N/A | AP36: KTL | AQ36: #N/A | AR36: #N/A | AS36: -2 | AT36: #N/A | AU36: 1614.7987 | AV36: -1653.3267 | AW36: -272.50889 | AX36: #N/A | AY36: #N/A | AZ36: #N/A
A37: TMO2002 | B37: Structure | C37: TMO2002-T01 | E37: Schedule 2 | F37: Active | G37: Towercom | H37: Towercom | I37: Towercom | J37: 1 | K37: Full SRF | L37: Full SAF | M37: 1 | O37: Lattice Tower | P37: Type - ARU - 1 | Q37: 83 | T37: 1 | U37: 0 | W37: 1 | X37: 118921 | Y37: 264516 | Z37: 53.624354 | AA37: -9.226138 | AB37: 46620.958 | AG37: DEL-6 A-E | AH37: 0 | AI37: town | AJ37: 57 | AK37: flat | AL37: 26 | AM37: Pad | AN37: Concrete Grade: Main Rebar: Corner/Secondary Rebar: Concrete Quantity (m3): Reinforcement Quantity (kg): | AO37: 0 | AP37: Obelisk | AQ37: 0 | AR37: 0 | AS37: -6.5 | AT37: 0 | AU37: 1663.9477 | AV37: -1708.1267 | AW37: -282.28222 | AX37: 0.65 | AY37: 0.35 | AZ37: Green
A38: TDL5019 | B38: Structure | C38: TDL5019-T01 | E38: MLA | F38: Active | G38: Vodafone | H38: Towercom | I38: Vodafone | J38: 1 | K38: Full SRF | L38: Full SAF | M38: 1 | O38: Lattice Tower | P38: Eve Type 6 | Q38: 15 | T38: 1 | U38: 0 | W38: 1 | X38: 192067 | Y38: 369961 | Z38: 54.57787 | AA38: -8.12343 | AB38: 46585.958 | AG38: FL104 | AH38: 1993-1996 | AI38: Country | AJ38: 58 | AK38: Flat | AL38: 26.5 | AM38: Slab | AN38: Concrete Grade: Main Rebar: Corner/Secondary Rebar: Concrete Quantity (m3): Reinforcement Quantity (kg): | AO38: 0 | AP38: KTL | AQ38: 0 | AR38: 0 | AS38: -11 | AT38: 0 | AU38: 1713.0967 | AV38: -1762.9267 | AW38: -292.05556 | AX38: 0.7 | AY38: 0.3 | AZ38: Green
A39: TCN5015 | B39: Structure | C39: TCN5015-T01 | D39: TCN7401 | E39: MLA | F39: UTS | G39: Vodafone | H39: Towercom | I39: Vodafone | J39: 1 | K39: Full SRF | L39: Full SAF | M39: 1 | O39: Wooden Pole | P39: Wooden Pole | Q39: 10 | T39: 0 | U39: 0 | W39: 0 | X39: 238788 | Y39: 298142 | Z39: 53.93129 | AA39: -7.41024 | AB39: 46183.958 | AG39: DEL-6 A-E | AH39: 1990-2001 | AI39: town | AJ39: 59 | AK39: Flat | AL39: 25.5 | AM39: Pile | AN39: Concrete Grade: Main Rebar: Corner/Secondary Rebar: Concrete Quantity (m3): Reinforcement Quantity (kg): | AO39: 0 | AP39: Obelisk | AQ39: 0 | AR39: 0 | AS39: -15.5 | AT39: 0 | AU39: 1762.2457 | AV39: -1817.7267 | AW39: -301.82889 | AX39: 0.95 | AY39: 0.05 | AZ39: Red
A40: TDU5020 | B40: Structure | C40: TDU5020-T01 | E40: MLA | F40: Active | G40: Vodafone | H40: Towercom | I40: Vodafone | J40: 1 | K40: Full SRF | L40: Full SAF | M40: 1 | O40: Lattice Tower | P40: Eve Type 5 | Q40: 20 | T40: 1 | U40: 1 | V40: latchway | W40: 1 | X40: 313418 | Y40: 226918 | Z40: 53.2807 | AA40: -6.30034 | AB40: 46228.958 | AG40: FL105 | AH40: 1993-1996 | AI40: Town | AJ40: 60 | AK40: Flat | AL40: 25 | AM40: Pad | AN40: Concrete Grade: Main Rebar: Corner/Secondary Rebar: Concrete Quantity (m3): Reinforcement Quantity (kg): | AO40: 4.4 x 4.4 x 1.2 | AP40: KTL | AQ40: 0 | AR40: Headframe | AS40: -20 | AT40: 0 | AU40: 1811.3947 | AV40: -1872.5267 | AW40: -311.60222 | AX40: 0.9 | AY40: 0.1 | AZ40: Amber
A41: TLS5013 | B41: Structure | C41: TLS5013-T01 | D41: TLS7402 | E41: MLA | F41: Retired | G41: Vodafone | H41: Towercom | I41: Vodafone | J41: 0 | K41: No SRF | L41: TL Only | M41: 0 | T41: 0 | U41: 0 | W41: 0 | X41: 237246 | Y41: 181356 | Z41: 52.88214 | AA41: -7.44748 | AG41: DEL-6 A-E | AH41: #N/A | AI41: #N/A | AJ41: 61 | AK41: #N/A | AL41: #N/A | AM41: Slab | AN41: Concrete Grade: Main Rebar: Corner/Secondary Rebar: Concrete Quantity (m3): Reinforcement Quantity (kg): | AO41: #N/A | AP41: Obelisk | AQ41: #N/A | AR41: #N/A | AS41: -24.5 | AT41: #N/A | AU41: 1860.5437 | AV41: -1927.3267 | AW41: -321.37556 | AX41: #N/A | AY41: #N/A | AZ41: #N/A
...

Sheet CUSTOMER PRESENCE
A1: Site | B1: Customer | C1: Customer Site ID | D1: Presence Type | E1: check
A2: TCK5002 | B2: 72 | C2: CKAHA | D2: Installed | E2: =MATCH(A2,'SITES TEST DATA'!A:A,0) -> 2
A3: TGY5003 | B3: 72 | C3: GYADN | D3: Licenced | E3: =MATCH(A3,'SITES TEST DATA'!A:A,0) -> 4
A4: TWW5005 | B4: 72 | C4: WWAKW | D4: Installed | E4: =MATCH(A4,'SITES TEST DATA'!A:A,0) -> 6
A5: TWW5004 | B5: 72 | C5: WW004 | D5: Licenced | E5: =MATCH(A5,'SITES TEST DATA'!A:A,0) -> 7
A6: TCN5006 | B6: 72 | C6: CN027 | D6: Installed | E6: =MATCH(A6,'SITES TEST DATA'!A:A,0) -> 9
A7: TGY5008 | B7: 72 | C7: GYANR | D7: Licenced | E7: =MATCH(A7,'SITES TEST DATA'!A:A,0) -> 11
A8: TWH4001 | B8: 72 | C8: WH013 | D8: Installed | E8: =MATCH(A8,'SITES TEST DATA'!A:A,0) -> 12
A9: TLK5009 | B9: 72 | C9: LKATD | D9: Licenced | E9: =MATCH(A9,'SITES TEST DATA'!A:A,0) -> 13
